[2023-12-05 16:29:17,877] [autoreload.py:677] [autoreload:run_with_reloader] [INFO]- Watching for file changes with StatReloader
[2023-12-05 16:29:43,154] [basehttp.py:187] [basehttp:log_message] [INFO]- "POST /api/getmain/ HTTP/1.1" 200 789
[2023-12-05 16:34:05,144] [log.py:241] [log:log_response] [ERROR]- Internal Server Error: /api/deletecommodity/
Traceback (most recent call last):
  File "D:\baiduwangpan\python_virtualenv\python_vx\lib\site-packages\django\core\handlers\exception.py", line 55, in inner
    response = get_response(request)
  File "D:\baiduwangpan\python_virtualenv\python_vx\lib\site-packages\django\core\handlers\base.py", line 204, in _get_response
    self.check_response(response, callback)
  File "D:\baiduwangpan\python_virtualenv\python_vx\lib\site-packages\django\core\handlers\base.py", line 332, in check_response
    raise ValueError(
ValueError: The view StudentExamination.views.deleteCommodity didn't return an HttpResponse object. It returned None instead.
[2023-12-05 16:34:05,159] [basehttp.py:187] [basehttp:log_message] [ERROR]- "POST /api/deletecommodity/ HTTP/1.1" 500 145
[2023-12-05 16:37:30,264] [autoreload.py:266] [autoreload:trigger_reload] [INFO]- D:\02_Program\04_Examination\Examination\StudentExamination\views.py changed, reloading.
[2023-12-05 16:37:31,230] [autoreload.py:677] [autoreload:run_with_reloader] [INFO]- Watching for file changes with StatReloader
[2023-12-05 16:37:35,047] [basehttp.py:187] [basehttp:log_message] [INFO]- "POST /api/deletecommodity/ HTTP/1.1" 200 61
[2023-12-05 16:37:41,246] [basehttp.py:187] [basehttp:log_message] [INFO]- "POST /api/deletecommodity/ HTTP/1.1" 200 111
[2023-12-05 16:38:01,881] [autoreload.py:266] [autoreload:trigger_reload] [INFO]- D:\02_Program\04_Examination\Examination\StudentExamination\views.py changed, reloading.
[2023-12-05 16:38:02,881] [autoreload.py:677] [autoreload:run_with_reloader] [INFO]- Watching for file changes with StatReloader
[2023-12-05 16:38:05,998] [basehttp.py:187] [basehttp:log_message] [INFO]- "POST /api/deletecommodity/ HTTP/1.1" 200 81
[2023-12-05 16:38:16,411] [autoreload.py:266] [autoreload:trigger_reload] [INFO]- D:\02_Program\04_Examination\Examination\StudentExamination\views.py changed, reloading.
[2023-12-05 16:38:17,354] [autoreload.py:677] [autoreload:run_with_reloader] [INFO]- Watching for file changes with StatReloader
[2023-12-05 16:38:18,380] [basehttp.py:187] [basehttp:log_message] [INFO]- "POST /api/deletecommodity/ HTTP/1.1" 200 81
[2023-12-05 16:38:25,355] [autoreload.py:266] [autoreload:trigger_reload] [INFO]- D:\02_Program\04_Examination\Examination\StudentExamination\views.py changed, reloading.
[2023-12-05 16:38:26,343] [autoreload.py:677] [autoreload:run_with_reloader] [INFO]- Watching for file changes with StatReloader
[2023-12-05 16:38:27,945] [autoreload.py:266] [autoreload:trigger_reload] [INFO]- D:\02_Program\04_Examination\Examination\StudentExamination\views.py changed, reloading.
[2023-12-05 16:38:29,153] [autoreload.py:677] [autoreload:run_with_reloader] [INFO]- Watching for file changes with StatReloader
[2023-12-05 16:38:30,973] [basehttp.py:187] [basehttp:log_message] [INFO]- "POST /api/deletecommodity/ HTTP/1.1" 200 46
[2023-12-05 16:38:53,621] [basehttp.py:187] [basehttp:log_message] [INFO]- "POST /api/updata/ HTTP/1.1" 200 61
[2023-12-05 16:39:02,208] [basehttp.py:187] [basehttp:log_message] [INFO]- "POST /api/getonedata/ HTTP/1.1" 200 52
[2023-12-05 16:39:13,055] [basehttp.py:187] [basehttp:log_message] [INFO]- "POST /api/updata/ HTTP/1.1" 200 61
[2023-12-05 16:39:32,658] [basehttp.py:187] [basehttp:log_message] [INFO]- "POST /api/getmain/ HTTP/1.1" 200 520
[2023-12-05 16:41:12,469] [autoreload.py:266] [autoreload:trigger_reload] [INFO]- D:\02_Program\04_Examination\Examination\StudentExamination\views.py changed, reloading.
[2023-12-05 16:41:13,516] [autoreload.py:677] [autoreload:run_with_reloader] [INFO]- Watching for file changes with StatReloader
[2023-12-05 16:41:31,642] [basehttp.py:187] [basehttp:log_message] [INFO]- "POST /api/updata/ HTTP/1.1" 200 61
[2023-12-05 16:42:06,471] [autoreload.py:266] [autoreload:trigger_reload] [INFO]- D:\02_Program\04_Examination\Examination\StudentExamination\views.py changed, reloading.
[2023-12-05 16:42:07,593] [autoreload.py:677] [autoreload:run_with_reloader] [INFO]- Watching for file changes with StatReloader
[2023-12-05 16:42:10,842] [basehttp.py:187] [basehttp:log_message] [INFO]- "POST /api/updata/ HTTP/1.1" 200 61
[2023-12-05 16:42:58,334] [autoreload.py:266] [autoreload:trigger_reload] [INFO]- D:\02_Program\04_Examination\Examination\StudentExamination\views.py changed, reloading.
[2023-12-05 16:42:59,314] [autoreload.py:677] [autoreload:run_with_reloader] [INFO]- Watching for file changes with StatReloader
[2023-12-05 16:43:08,336] [autoreload.py:266] [autoreload:trigger_reload] [INFO]- D:\02_Program\04_Examination\Examination\StudentExamination\views.py changed, reloading.
[2023-12-05 16:43:09,557] [autoreload.py:677] [autoreload:run_with_reloader] [INFO]- Watching for file changes with StatReloader
[2023-12-05 16:43:33,508] [basehttp.py:187] [basehttp:log_message] [INFO]- "POST /api/addmain/ HTTP/1.1" 200 49
[2023-12-05 16:43:41,550] [basehttp.py:187] [basehttp:log_message] [INFO]- "POST /api/addmain/ HTTP/1.1" 200 279
[2023-12-05 16:44:19,984] [basehttp.py:187] [basehttp:log_message] [INFO]- "POST /api/addmain/ HTTP/1.1" 200 39
[2023-12-05 16:44:50,402] [autoreload.py:266] [autoreload:trigger_reload] [INFO]- D:\02_Program\04_Examination\Examination\StudentExamination\views.py changed, reloading.
[2023-12-05 16:44:51,313] [autoreload.py:677] [autoreload:run_with_reloader] [INFO]- Watching for file changes with StatReloader
[2023-12-05 16:45:01,451] [autoreload.py:266] [autoreload:trigger_reload] [INFO]- D:\02_Program\04_Examination\Examination\StudentExamination\views.py changed, reloading.
[2023-12-05 16:45:02,398] [autoreload.py:677] [autoreload:run_with_reloader] [INFO]- Watching for file changes with StatReloader
[2023-12-05 16:45:07,075] [basehttp.py:187] [basehttp:log_message] [INFO]- "POST /api/addmain/ HTTP/1.1" 200 45
[2023-12-05 16:45:13,162] [basehttp.py:187] [basehttp:log_message] [INFO]- "POST /api/getmain/ HTTP/1.1" 200 791
[2023-12-05 13:01:05,865] [log.py:241] [log:log_response] [WARNING]- Not Found: /api/v1/dashboard/base/all/all
[2023-12-05 14:06:00,667] [log.py:241] [log:log_response] [WARNING]- Not Found: /api/v1/settings/upgrade
[2023-12-05 14:06:52,017] [log.py:241] [log:log_response] [WARNING]- Not Found: /api/v1/dashboard/base/all/all
[2023-12-05 15:31:27,001] [log.py:241] [log:log_response] [WARNING]- Not Found: /api/v1/auth/issafety
[2023-12-05 16:56:21,155] [log.py:241] [log:log_response] [WARNING]- Not Found: /api/v1/settings/upgrade
[2023-12-05 18:54:49,039] [log.py:241] [log:log_response] [WARNING]- Not Found: /api/v1/auth/issafety
[2023-12-05 19:44:59,517] [log.py:241] [log:log_response] [WARNING]- Not Found: /api/v1/settings/search
[2023-12-05 19:49:30,943] [log.py:241] [log:log_response] [WARNING]- Not Found: /api/v1/auth/language
[2023-12-05 20:54:20,567] [log.py:241] [log:log_response] [ERROR]- Internal Server Error: /api/getxx/
Traceback (most recent call last):
  File "/home/an/python_examin/lib/python3.9/site-packages/django/core/handlers/exception.py", line 55, in inner
    response = get_response(request)
  File "/home/an/python_examin/lib/python3.9/site-packages/django/core/handlers/base.py", line 197, in _get_response
    response = wrapped_callback(request, *callback_args, **callback_kwargs)
  File "./StudentExamination/views.py", line 288, in get_Logistic
    data = data["data"]["track_info"]["tracking"]["providers"][0]["events"]
KeyError: 'track_info'
[2023-12-05 21:04:14,720] [log.py:241] [log:log_response] [WARNING]- Not Found: /api/v1/monitors/netoptions
[2023-12-05 21:04:20,689] [log.py:241] [log:log_response] [ERROR]- Internal Server Error: /api/getxx/
Traceback (most recent call last):
  File "/home/an/python_examin/lib/python3.9/site-packages/django/core/handlers/exception.py", line 55, in inner
    response = get_response(request)
  File "/home/an/python_examin/lib/python3.9/site-packages/django/core/handlers/base.py", line 197, in _get_response
    response = wrapped_callback(request, *callback_args, **callback_kwargs)
  File "./StudentExamination/views.py", line 288, in get_Logistic
    data = data["data"]["track_info"]["tracking"]["providers"][0]["events"]
KeyError: 'track_info'
[2023-12-05 21:24:20,795] [log.py:241] [log:log_response] [ERROR]- Internal Server Error: /api/getxx/
Traceback (most recent call last):
  File "/home/an/python_examin/lib/python3.9/site-packages/django/core/handlers/exception.py", line 55, in inner
    response = get_response(request)
  File "/home/an/python_examin/lib/python3.9/site-packages/django/core/handlers/base.py", line 197, in _get_response
    response = wrapped_callback(request, *callback_args, **callback_kwargs)
  File "./StudentExamination/views.py", line 288, in get_Logistic
    data = data["data"]["track_info"]["tracking"]["providers"][0]["events"]
KeyError: 'track_info'
[2023-12-05 21:54:20,884] [log.py:241] [log:log_response] [ERROR]- Internal Server Error: /api/getxx/
Traceback (most recent call last):
  File "/home/an/python_examin/lib/python3.9/site-packages/django/core/handlers/exception.py", line 55, in inner
    response = get_response(request)
  File "/home/an/python_examin/lib/python3.9/site-packages/django/core/handlers/base.py", line 197, in _get_response
    response = wrapped_callback(request, *callback_args, **callback_kwargs)
  File "./StudentExamination/views.py", line 288, in get_Logistic
    data = data["data"]["track_info"]["tracking"]["providers"][0]["events"]
KeyError: 'track_info'
[2023-12-05 22:45:01,264] [log.py:241] [log:log_response] [WARNING]- Not Found: /api/v1/settings/upgrade
[2023-12-05 23:52:11,480] [log.py:241] [log:log_response] [WARNING]- Not Found: /api/v1/auth/demo
[2023-12-06 02:01:57,294] [log.py:241] [log:log_response] [WARNING]- Not Found: /api/v1/auth/demo
[2023-12-06 03:19:02,371] [log.py:241] [log:log_response] [WARNING]- Not Found: /api/v1/monitors/iooptions
[2023-12-06 04:30:56,507] [log.py:241] [log:log_response] [WARNING]- Not Found: /api/config/getClientIp
[2023-12-06 04:33:41,621] [log.py:241] [log:log_response] [WARNING]- Not Found: /api/v1/settings/search
[2023-12-06 04:42:33,496] [log.py:241] [log:log_response] [WARNING]- Not Found: /api/v1/auth/language
[2023-12-06 05:05:16,062] [log.py:241] [log:log_response] [WARNING]- Not Found: /api/v1/monitors/netoptions
[2023-12-06 06:00:53,591] [log.py:241] [log:log_response] [WARNING]- Not Found: /api/v1/auth/demo
[2023-12-06 07:22:51,317] [log.py:241] [log:log_response] [WARNING]- Not Found: /api/v1/auth/captcha
[2023-12-06 08:18:46,876] [log.py:241] [log:log_response] [WARNING]- Not Found: /api/v1/settings/search
[2023-12-06 09:12:26,326] [log.py:241] [log:log_response] [WARNING]- Not Found: /api/v1/settings/search
[2023-12-06 10:43:08,586] [log.py:241] [log:log_response] [WARNING]- Not Found: /api/v1/auth/demo
[2023-12-06 11:52:30,614] [log.py:241] [log:log_response] [WARNING]- Not Found: /api/config/getClientIp
[2023-12-06 12:35:55,139] [log.py:241] [log:log_response] [WARNING]- Not Found: /api/session/properties
[2023-12-06 16:23:03,789] [log.py:241] [log:log_response] [WARNING]- Not Found: /api/v1/auth/captcha
[2023-12-06 17:04:47,146] [log.py:241] [log:log_response] [WARNING]- Not Found: /api/v1/settings/search
[2023-12-06 20:19:38,591] [log.py:241] [log:log_response] [WARNING]- Not Found: /api/session/properties
[2023-12-06 22:36:01,950] [log.py:241] [log:log_response] [WARNING]- Not Found: /api/v1/auth/captcha
[2023-12-07 04:19:38,246] [log.py:241] [log:log_response] [WARNING]- Not Found: /api/v1/auth/language
[2023-12-07 04:23:52,045] [log.py:241] [log:log_response] [WARNING]- Not Found: /api/v1/auth/language
[2023-12-07 06:18:14,288] [log.py:241] [log:log_response] [WARNING]- Not Found: /api/v1/auth/demo
[2023-12-07 07:09:35,460] [log.py:241] [log:log_response] [WARNING]- Not Found: /api/session/properties
[2023-12-07 08:33:57,734] [log.py:241] [log:log_response] [WARNING]- Not Found: /api/v1/settings/upgrade
[2023-12-07 10:33:20,312] [log.py:241] [log:log_response] [WARNING]- Not Found: /api/v1/dashboard/base/all/all
[2023-12-07 11:49:51,063] [log.py:241] [log:log_response] [WARNING]- Not Found: /api/v1/auth/language
[2023-12-07 11:53:51,878] [log.py:241] [log:log_response] [WARNING]- Not Found: /api/v1/monitors/netoptions
[2023-12-07 11:54:31,602] [log.py:241] [log:log_response] [WARNING]- Not Found: /api/v1/settings/search
[2023-12-07 12:23:05,762] [log.py:241] [log:log_response] [WARNING]- Not Found: /api/v1/monitors/iooptions
[2023-12-07 13:01:00,793] [log.py:241] [log:log_response] [WARNING]- Not Found: /api/v1/auth/language
[2023-12-07 13:08:31,422] [log.py:241] [log:log_response] [WARNING]- Not Found: /api/v1/auth/issafety
[2023-12-07 14:57:37,033] [log.py:241] [log:log_response] [WARNING]- Not Found: /api/v1/auth/demo
[2023-12-07 15:03:12,830] [log.py:241] [log:log_response] [WARNING]- Not Found: /api/v1/auth/language
[2023-12-07 15:21:03,508] [log.py:241] [log:log_response] [WARNING]- Not Found: /api/v1/settings/upgrade
[2023-12-07 15:27:16,359] [log.py:241] [log:log_response] [WARNING]- Not Found: /api/v1/auth/language
[2023-12-07 15:40:43,386] [log.py:241] [log:log_response] [WARNING]- Not Found: /api/v1/dashboard/base/all/all
[2023-12-07 16:28:02,207] [log.py:241] [log:log_response] [WARNING]- Not Found: /api/config/getClientIp
[2023-12-07 18:59:20,904] [log.py:241] [log:log_response] [WARNING]- Not Found: /api/v1/auth/issafety
[2023-12-07 19:03:24,873] [log.py:241] [log:log_response] [ERROR]- Internal Server Error: /api/getxx/
Traceback (most recent call last):
  File "/home/an/python_examin/lib/python3.9/site-packages/django/core/handlers/exception.py", line 55, in inner
    response = get_response(request)
  File "/home/an/python_examin/lib/python3.9/site-packages/django/core/handlers/base.py", line 197, in _get_response
    response = wrapped_callback(request, *callback_args, **callback_kwargs)
  File "./StudentExamination/views.py", line 288, in get_Logistic
    data = data["data"]["track_info"]["tracking"]["providers"][0]["events"]
KeyError: 'track_info'
[2023-12-07 19:13:24,969] [log.py:241] [log:log_response] [ERROR]- Internal Server Error: /api/getxx/
Traceback (most recent call last):
  File "/home/an/python_examin/lib/python3.9/site-packages/django/core/handlers/exception.py", line 55, in inner
    response = get_response(request)
  File "/home/an/python_examin/lib/python3.9/site-packages/django/core/handlers/base.py", line 197, in _get_response
    response = wrapped_callback(request, *callback_args, **callback_kwargs)
  File "./StudentExamination/views.py", line 288, in get_Logistic
    data = data["data"]["track_info"]["tracking"]["providers"][0]["events"]
KeyError: 'track_info'
[2023-12-07 19:33:25,067] [log.py:241] [log:log_response] [ERROR]- Internal Server Error: /api/getxx/
Traceback (most recent call last):
  File "/home/an/python_examin/lib/python3.9/site-packages/django/core/handlers/exception.py", line 55, in inner
    response = get_response(request)
  File "/home/an/python_examin/lib/python3.9/site-packages/django/core/handlers/base.py", line 197, in _get_response
    response = wrapped_callback(request, *callback_args, **callback_kwargs)
  File "./StudentExamination/views.py", line 288, in get_Logistic
    data = data["data"]["track_info"]["tracking"]["providers"][0]["events"]
KeyError: 'track_info'
[2023-12-07 20:03:25,170] [log.py:241] [log:log_response] [ERROR]- Internal Server Error: /api/getxx/
Traceback (most recent call last):
  File "/home/an/python_examin/lib/python3.9/site-packages/django/core/handlers/exception.py", line 55, in inner
    response = get_response(request)
  File "/home/an/python_examin/lib/python3.9/site-packages/django/core/handlers/base.py", line 197, in _get_response
    response = wrapped_callback(request, *callback_args, **callback_kwargs)
  File "./StudentExamination/views.py", line 288, in get_Logistic
    data = data["data"]["track_info"]["tracking"]["providers"][0]["events"]
KeyError: 'track_info'
[2023-12-07 20:29:44,860] [log.py:241] [log:log_response] [WARNING]- Not Found: /api/v1/settings/search
[2023-12-08 01:08:58,832] [log.py:241] [log:log_response] [WARNING]- Not Found: /api/v1/monitors/netoptions
[2023-12-08 01:59:33,194] [log.py:241] [log:log_response] [WARNING]- Not Found: /api/v1/auth/issafety
[2023-12-08 02:21:56,836] [log.py:241] [log:log_response] [WARNING]- Not Found: /api/v1/auth/issafety
[2023-12-08 04:13:42,638] [log.py:241] [log:log_response] [ERROR]- Internal Server Error: /api/getxx/
Traceback (most recent call last):
  File "/home/an/python_examin/lib/python3.9/site-packages/django/core/handlers/exception.py", line 55, in inner
    response = get_response(request)
  File "/home/an/python_examin/lib/python3.9/site-packages/django/core/handlers/base.py", line 197, in _get_response
    response = wrapped_callback(request, *callback_args, **callback_kwargs)
  File "./StudentExamination/views.py", line 288, in get_Logistic
    data = data["data"]["track_info"]["tracking"]["providers"][0]["events"]
KeyError: 'track_info'
[2023-12-08 04:23:42,738] [log.py:241] [log:log_response] [ERROR]- Internal Server Error: /api/getxx/
Traceback (most recent call last):
  File "/home/an/python_examin/lib/python3.9/site-packages/django/core/handlers/exception.py", line 55, in inner
    response = get_response(request)
  File "/home/an/python_examin/lib/python3.9/site-packages/django/core/handlers/base.py", line 197, in _get_response
    response = wrapped_callback(request, *callback_args, **callback_kwargs)
  File "./StudentExamination/views.py", line 288, in get_Logistic
    data = data["data"]["track_info"]["tracking"]["providers"][0]["events"]
KeyError: 'track_info'
[2023-12-08 04:43:42,829] [log.py:241] [log:log_response] [ERROR]- Internal Server Error: /api/getxx/
Traceback (most recent call last):
  File "/home/an/python_examin/lib/python3.9/site-packages/django/core/handlers/exception.py", line 55, in inner
    response = get_response(request)
  File "/home/an/python_examin/lib/python3.9/site-packages/django/core/handlers/base.py", line 197, in _get_response
    response = wrapped_callback(request, *callback_args, **callback_kwargs)
  File "./StudentExamination/views.py", line 288, in get_Logistic
    data = data["data"]["track_info"]["tracking"]["providers"][0]["events"]
KeyError: 'track_info'
[2023-12-08 05:13:42,921] [log.py:241] [log:log_response] [ERROR]- Internal Server Error: /api/getxx/
Traceback (most recent call last):
  File "/home/an/python_examin/lib/python3.9/site-packages/django/core/handlers/exception.py", line 55, in inner
    response = get_response(request)
  File "/home/an/python_examin/lib/python3.9/site-packages/django/core/handlers/base.py", line 197, in _get_response
    response = wrapped_callback(request, *callback_args, **callback_kwargs)
  File "./StudentExamination/views.py", line 288, in get_Logistic
    data = data["data"]["track_info"]["tracking"]["providers"][0]["events"]
KeyError: 'track_info'
[2023-12-08 05:56:00,064] [log.py:241] [log:log_response] [WARNING]- Not Found: /api/v1/dashboard/base/all/all
[2023-12-08 07:34:20,553] [log.py:241] [log:log_response] [WARNING]- Not Found: /api/v1/settings/search
[2023-12-08 08:29:27,326] [log.py:241] [log:log_response] [WARNING]- Not Found: /api/v1/auth/issafety
[2023-12-08 09:26:12,898] [log.py:241] [log:log_response] [WARNING]- Not Found: /api/language/zh-cn/lang.js
[2023-12-08 09:26:13,669] [log.py:241] [log:log_response] [WARNING]- Not Found: /api/v1/auth/demo
[2023-12-08 11:00:31,962] [exception.py:124] [exception:response_for_exception] [ERROR]- Invalid HTTP_HOST header: 'srv57c0d2365c3c.korsan.me:443srv57c0d2365c3c.korsan.me:443'. The domain name provided is not valid according to RFC 1034/1035.
Traceback (most recent call last):
  File "/home/an/python_examin/lib/python3.9/site-packages/django/core/handlers/exception.py", line 55, in inner
    response = get_response(request)
  File "/home/an/python_examin/lib/python3.9/site-packages/django/utils/deprecation.py", line 135, in __call__
    response = self.process_request(request)
  File "/home/an/python_examin/lib/python3.9/site-packages/django/middleware/common.py", line 48, in process_request
    host = request.get_host()
  File "/home/an/python_examin/lib/python3.9/site-packages/django/http/request.py", line 148, in get_host
    raise DisallowedHost(msg)
django.core.exceptions.DisallowedHost: Invalid HTTP_HOST header: 'srv57c0d2365c3c.korsan.me:443srv57c0d2365c3c.korsan.me:443'. The domain name provided is not valid according to RFC 1034/1035.
[2023-12-08 11:00:32,010] [log.py:241] [log:log_response] [WARNING]- Bad Request: /
[2023-12-08 11:19:14,861] [exception.py:124] [exception:response_for_exception] [ERROR]- Invalid HTTP_HOST header: 'srv57c0d2365c3c.korsan.me:443srv57c0d2365c3c.korsan.me:443'. The domain name provided is not valid according to RFC 1034/1035.
Traceback (most recent call last):
  File "/home/an/python_examin/lib/python3.9/site-packages/django/core/handlers/exception.py", line 55, in inner
    response = get_response(request)
  File "/home/an/python_examin/lib/python3.9/site-packages/django/utils/deprecation.py", line 135, in __call__
    response = self.process_request(request)
  File "/home/an/python_examin/lib/python3.9/site-packages/django/middleware/common.py", line 48, in process_request
    host = request.get_host()
  File "/home/an/python_examin/lib/python3.9/site-packages/django/http/request.py", line 148, in get_host
    raise DisallowedHost(msg)
django.core.exceptions.DisallowedHost: Invalid HTTP_HOST header: 'srv57c0d2365c3c.korsan.me:443srv57c0d2365c3c.korsan.me:443'. The domain name provided is not valid according to RFC 1034/1035.
[2023-12-08 11:19:14,862] [log.py:241] [log:log_response] [WARNING]- Bad Request: /
[2023-12-08 16:48:50,469] [log.py:241] [log:log_response] [WARNING]- Not Found: /api/v1/auth/language
[2023-12-08 16:53:01,218] [log.py:241] [log:log_response] [WARNING]- Not Found: /api/v1/auth/captcha
[2023-12-09 02:27:45,947] [log.py:241] [log:log_response] [WARNING]- Not Found: /api/v1/auth/captcha
[2023-12-09 03:38:01,309] [log.py:241] [log:log_response] [WARNING]- Not Found: /api/v1/auth/issafety
[2023-12-09 04:27:57,868] [log.py:241] [log:log_response] [WARNING]- Not Found: /api/v1/settings/upgrade
[2023-12-09 04:50:02,868] [log.py:241] [log:log_response] [WARNING]- Not Found: /api/v1/auth/issafety
[2023-12-09 05:25:22,868] [log.py:241] [log:log_response] [WARNING]- Not Found: /api/v1/auth/language
[2023-12-09 05:37:24,489] [log.py:241] [log:log_response] [WARNING]- Not Found: /api/v1/auth/language
[2023-12-09 07:56:35,980] [log.py:241] [log:log_response] [WARNING]- Not Found: /api/v1/settings/search
[2023-12-09 08:12:23,753] [log.py:241] [log:log_response] [WARNING]- Not Found: /api/v1/auth/issafety
[2023-12-09 09:01:39,159] [log.py:241] [log:log_response] [WARNING]- Not Found: /api/v1/auth/issafety
[2023-12-09 10:50:39,809] [log.py:241] [log:log_response] [WARNING]- Not Found: /api/v1/auth/captcha
[2023-12-09 10:52:03,603] [log.py:241] [log:log_response] [WARNING]- Not Found: /api/v1/settings/upgrade
[2023-12-09 13:46:58,814] [log.py:241] [log:log_response] [WARNING]- Not Found: /api/v1/settings/search
[2023-12-09 13:58:29,069] [log.py:241] [log:log_response] [WARNING]- Not Found: /api/v1/auth/issafety
[2023-12-09 15:01:14,705] [log.py:241] [log:log_response] [WARNING]- Not Found: /api/v1/auth/language
[2023-12-09 15:20:00,486] [log.py:241] [log:log_response] [WARNING]- Not Found: /api/v1/monitors/iooptions
[2023-12-09 15:27:24,933] [log.py:241] [log:log_response] [WARNING]- Not Found: /api/v1/settings/search
[2023-12-09 19:53:57,277] [log.py:241] [log:log_response] [WARNING]- Not Found: /api/v1/auth/captcha
[2023-12-10 00:05:17,591] [log.py:241] [log:log_response] [WARNING]- Not Found: /api/v1/monitors/iooptions
[2023-12-10 00:23:46,062] [log.py:241] [log:log_response] [WARNING]- Not Found: /api/v1/auth/captcha
[2023-12-10 03:33:13,253] [log.py:241] [log:log_response] [WARNING]- Not Found: /api/v2/cmdb/system/admin
[2023-12-10 07:02:08,092] [log.py:241] [log:log_response] [ERROR]- Internal Server Error: /api/getxx/
Traceback (most recent call last):
  File "/home/an/python_examin/lib/python3.9/site-packages/django/core/handlers/exception.py", line 55, in inner
    response = get_response(request)
  File "/home/an/python_examin/lib/python3.9/site-packages/django/core/handlers/base.py", line 197, in _get_response
    response = wrapped_callback(request, *callback_args, **callback_kwargs)
  File "./StudentExamination/views.py", line 288, in get_Logistic
    data = data["data"]["track_info"]["tracking"]["providers"][0]["events"]
KeyError: 'track_info'
[2023-12-10 07:12:08,194] [log.py:241] [log:log_response] [ERROR]- Internal Server Error: /api/getxx/
Traceback (most recent call last):
  File "/home/an/python_examin/lib/python3.9/site-packages/django/core/handlers/exception.py", line 55, in inner
    response = get_response(request)
  File "/home/an/python_examin/lib/python3.9/site-packages/django/core/handlers/base.py", line 197, in _get_response
    response = wrapped_callback(request, *callback_args, **callback_kwargs)
  File "./StudentExamination/views.py", line 288, in get_Logistic
    data = data["data"]["track_info"]["tracking"]["providers"][0]["events"]
KeyError: 'track_info'
[2023-12-10 07:32:08,288] [log.py:241] [log:log_response] [ERROR]- Internal Server Error: /api/getxx/
Traceback (most recent call last):
  File "/home/an/python_examin/lib/python3.9/site-packages/django/core/handlers/exception.py", line 55, in inner
    response = get_response(request)
  File "/home/an/python_examin/lib/python3.9/site-packages/django/core/handlers/base.py", line 197, in _get_response
    response = wrapped_callback(request, *callback_args, **callback_kwargs)
  File "./StudentExamination/views.py", line 288, in get_Logistic
    data = data["data"]["track_info"]["tracking"]["providers"][0]["events"]
KeyError: 'track_info'
[2023-12-10 08:02:08,383] [log.py:241] [log:log_response] [ERROR]- Internal Server Error: /api/getxx/
Traceback (most recent call last):
  File "/home/an/python_examin/lib/python3.9/site-packages/django/core/handlers/exception.py", line 55, in inner
    response = get_response(request)
  File "/home/an/python_examin/lib/python3.9/site-packages/django/core/handlers/base.py", line 197, in _get_response
    response = wrapped_callback(request, *callback_args, **callback_kwargs)
  File "./StudentExamination/views.py", line 288, in get_Logistic
    data = data["data"]["track_info"]["tracking"]["providers"][0]["events"]
KeyError: 'track_info'
[2023-12-10 09:14:12,487] [log.py:241] [log:log_response] [WARNING]- Not Found: /api/v1/monitors/netoptions
[2023-12-10 15:24:23,827] [log.py:241] [log:log_response] [WARNING]- Not Found: /api/v1/monitors/netoptions
[2023-12-10 15:30:08,988] [log.py:241] [log:log_response] [WARNING]- Not Found: /api/v1/auth/language
[2023-12-10 16:00:40,619] [log.py:241] [log:log_response] [WARNING]- Not Found: /api/v1/auth/demo
[2023-12-10 18:49:45,205] [log.py:241] [log:log_response] [WARNING]- Not Found: /api/v1/auth/captcha
[2023-12-10 20:25:53,073] [log.py:241] [log:log_response] [WARNING]- Not Found: /api/v1/auth/issafety
[2023-12-10 21:45:11,184] [log.py:241] [log:log_response] [WARNING]- Not Found: /api/v1/auth/demo
[2023-12-10 22:41:39,544] [log.py:241] [log:log_response] [WARNING]- Not Found: /api/v1/auth/captcha
[2023-12-10 23:13:25,288] [log.py:241] [log:log_response] [WARNING]- Not Found: /api/v1/monitors/iooptions
[2023-12-11 02:13:28,270] [log.py:241] [log:log_response] [WARNING]- Not Found: /api/v1/settings/search
[2023-12-11 04:35:12,341] [log.py:241] [log:log_response] [WARNING]- Not Found: /api/v1/auth/captcha
[2023-12-11 04:36:02,741] [log.py:241] [log:log_response] [WARNING]- Not Found: /api/v1/settings/upgrade
[2023-12-11 04:54:29,642] [log.py:241] [log:log_response] [WARNING]- Not Found: /api/v1/monitors/netoptions
[2023-12-11 05:53:42,299] [log.py:241] [log:log_response] [WARNING]- Not Found: /api/v1/settings/search
[2023-12-11 07:04:59,018] [log.py:241] [log:log_response] [WARNING]- Not Found: /api/v1/auth/issafety
[2023-12-11 07:17:35,662] [log.py:241] [log:log_response] [WARNING]- Not Found: /api/v1/auth/language
[2023-12-11 08:57:25,621] [log.py:241] [log:log_response] [WARNING]- Not Found: /api/v1/auth/demo
[2023-12-11 12:19:04,617] [log.py:241] [log:log_response] [WARNING]- Not Found: /api/v1/auth/captcha
[2023-12-11 12:49:28,659] [log.py:241] [log:log_response] [WARNING]- Not Found: /api/v1/dashboard/base/all/all
[2023-12-11 14:02:57,313] [log.py:241] [log:log_response] [WARNING]- Not Found: /api/v1/auth/language
[2023-12-11 15:09:50,471] [log.py:241] [log:log_response] [WARNING]- Not Found: /api/v1/auth/language
[2023-12-11 15:31:00,458] [log.py:241] [log:log_response] [WARNING]- Not Found: /api/v1/auth/issafety
[2023-12-11 21:57:43,587] [log.py:241] [log:log_response] [WARNING]- Not Found: /api/v1/settings/upgrade
[2023-12-11 22:30:27,571] [log.py:241] [log:log_response] [WARNING]- Not Found: /api/v1/monitors/iooptions
[2023-12-12 02:15:35,579] [log.py:241] [log:log_response] [WARNING]- Not Found: /api/v1/monitors/iooptions
[2023-12-12 02:40:03,677] [log.py:241] [log:log_response] [WARNING]- Not Found: /api/v1/monitors/netoptions
[2023-12-12 02:46:01,822] [log.py:241] [log:log_response] [WARNING]- Not Found: /api/v1/settings/upgrade
[2023-12-12 05:37:49,495] [log.py:241] [log:log_response] [WARNING]- Not Found: /api/v1/auth/issafety
[2023-12-12 08:08:50,936] [log.py:241] [log:log_response] [WARNING]- Not Found: /api/v1/settings/search
[2023-12-12 08:23:19,161] [log.py:241] [log:log_response] [WARNING]- Not Found: /api/v1/auth/language
[2023-12-12 12:29:59,263] [log.py:241] [log:log_response] [WARNING]- Not Found: /api/gtimg/timestamp=${1702384199198}
[2023-12-12 12:30:02,590] [log.py:241] [log:log_response] [WARNING]- Not Found: /api/gtimg/timestamp=${1702384202499}
[2023-12-12 12:32:16,896] [log.py:241] [log:log_response] [WARNING]- Not Found: /api/gtimg/&timestamp=${1702384336823}
[2023-12-12 12:32:21,284] [log.py:241] [log:log_response] [WARNING]- Not Found: /api/gtimg&timestamp=${1702384341222}
[2023-12-12 12:32:26,517] [log.py:241] [log:log_response] [WARNING]- Not Found: /api/gtimg&timestamp=${1702384346421}
[2023-12-12 12:32:37,313] [log.py:241] [log:log_response] [WARNING]- Not Found: /api/gtimg/&timestamp=${1702384357244}
[2023-12-12 12:32:39,528] [log.py:241] [log:log_response] [WARNING]- Not Found: /api/gtimg/timestamp=${1702384359466}
[2023-12-12 12:32:42,451] [log.py:241] [log:log_response] [WARNING]- Not Found: /api/gtimg/timestamp=${1702384362351}
[2023-12-12 12:51:52,865] [log.py:241] [log:log_response] [WARNING]- Not Found: /api/api/gtimg/
[2023-12-12 13:34:58,027] [log.py:241] [log:log_response] [WARNING]- Not Found: /api/v1/auth/language
[2023-12-12 13:58:49,892] [log.py:241] [log:log_response] [WARNING]- Not Found: /api/v1/auth/captcha
[2023-12-12 15:55:42,433] [log.py:241] [log:log_response] [WARNING]- Not Found: /api/v1/auth/demo
[2023-12-12 16:18:43,978] [log.py:241] [log:log_response] [WARNING]- Not Found: /api/v1/monitors/netoptions
[2023-12-12 17:16:41,245] [log.py:241] [log:log_response] [WARNING]- Not Found: /api/v1/dashboard/base/all/all
[2023-12-12 17:42:26,239] [log.py:241] [log:log_response] [WARNING]- Not Found: /api/v1/settings/search
[2023-12-12 17:51:32,420] [log.py:241] [log:log_response] [WARNING]- Not Found: /api/v1/auth/demo
[2023-12-12 18:02:02,387] [log.py:241] [log:log_response] [WARNING]- Not Found: /api/v1/auth/issafety
[2023-12-12 19:04:51,347] [log.py:241] [log:log_response] [WARNING]- Not Found: /api/v1/dashboard/base/all/all
[2023-12-12 21:38:52,301] [log.py:241] [log:log_response] [WARNING]- Not Found: /api/v1/monitors/netoptions
