[2024-01-10 08:58:22,492] [views.py:113] [views:gtimg] [INFO]- 验证码:VR04
[2024-01-10 08:58:40,769] [views.py:113] [views:gtimg] [INFO]- 验证码:C6XW
[2024-01-10 08:58:40,912] [views.py:113] [views:gtimg] [INFO]- 验证码:5FE5
[2024-01-10 08:58:41,194] [views.py:113] [views:gtimg] [INFO]- 验证码:JVH0
[2024-01-10 08:58:42,581] [log.py:241] [log:log_response] [ERROR]- Internal Server Error: /api/gtimg/
Traceback (most recent call last):
  File "/home/an/python3.9.12/lib/python3.9/site-packages/pymysql/connections.py", line 613, in connect
    sock = socket.create_connection(
  File "/home/an/python3.9.12/lib/python3.9/socket.py", line 844, in create_connection
    raise err
  File "/home/an/python3.9.12/lib/python3.9/socket.py", line 832, in create_connection
    sock.connect(sa)
socket.timeout: timed out

During handling of the above exception, another exception occurred:

Traceback (most recent call last):
  File "/home/an/python3.9.12/lib/python3.9/site-packages/django/db/backends/base/base.py", line 282, in ensure_connection
    self.connect()
  File "/home/an/python3.9.12/lib/python3.9/site-packages/django/utils/asyncio.py", line 26, in inner
    return func(*args, **kwargs)
  File "/home/an/python3.9.12/lib/python3.9/site-packages/django/db/backends/base/base.py", line 263, in connect
    self.connection = self.get_new_connection(conn_params)
  File "/home/an/python3.9.12/lib/python3.9/site-packages/django/utils/asyncio.py", line 26, in inner
    return func(*args, **kwargs)
  File "/home/an/python3.9.12/lib/python3.9/site-packages/django/db/backends/mysql/base.py", line 247, in get_new_connection
    connection = Database.connect(**conn_params)
  File "/home/an/python3.9.12/lib/python3.9/site-packages/pymysql/connections.py", line 353, in __init__
    self.connect()
  File "/home/an/python3.9.12/lib/python3.9/site-packages/pymysql/connections.py", line 664, in connect
    raise exc
pymysql.err.OperationalError: (2003, "Can't connect to MySQL server on '101.42.5.22' (timed out)")

The above exception was the direct cause of the following exception:

Traceback (most recent call last):
  File "/home/an/python3.9.12/lib/python3.9/site-packages/django/core/handlers/exception.py", line 55, in inner
    response = get_response(request)
  File "/home/an/python3.9.12/lib/python3.9/site-packages/django/utils/deprecation.py", line 138, in __call__
    response = self.process_response(request, response)
  File "/home/an/python3.9.12/lib/python3.9/site-packages/django/contrib/sessions/middleware.py", line 59, in process_response
    request.session.save()
  File "/home/an/python3.9.12/lib/python3.9/site-packages/django/contrib/sessions/backends/db.py", line 80, in save
    return self.create()
  File "/home/an/python3.9.12/lib/python3.9/site-packages/django/contrib/sessions/backends/db.py", line 50, in create
    self._session_key = self._get_new_session_key()
  File "/home/an/python3.9.12/lib/python3.9/site-packages/django/contrib/sessions/backends/base.py", line 150, in _get_new_session_key
    if not self.exists(session_key):
  File "/home/an/python3.9.12/lib/python3.9/site-packages/django/contrib/sessions/backends/db.py", line 46, in exists
    return self.model.objects.filter(session_key=session_key).exists()
  File "/home/an/python3.9.12/lib/python3.9/site-packages/django/db/models/query.py", line 1226, in exists
    return self.query.has_results(using=self.db)
  File "/home/an/python3.9.12/lib/python3.9/site-packages/django/db/models/sql/query.py", line 592, in has_results
    return compiler.has_results()
  File "/home/an/python3.9.12/lib/python3.9/site-packages/django/db/models/sql/compiler.py", line 1366, in has_results
    return bool(self.execute_sql(SINGLE))
  File "/home/an/python3.9.12/lib/python3.9/site-packages/django/db/models/sql/compiler.py", line 1396, in execute_sql
    cursor = self.connection.cursor()
  File "/home/an/python3.9.12/lib/python3.9/site-packages/django/utils/asyncio.py", line 26, in inner
    return func(*args, **kwargs)
  File "/home/an/python3.9.12/lib/python3.9/site-packages/django/db/backends/base/base.py", line 323, in cursor
    return self._cursor()
  File "/home/an/python3.9.12/lib/python3.9/site-packages/django/db/backends/base/base.py", line 299, in _cursor
    self.ensure_connection()
  File "/home/an/python3.9.12/lib/python3.9/site-packages/django/utils/asyncio.py", line 26, in inner
    return func(*args, **kwargs)
  File "/home/an/python3.9.12/lib/python3.9/site-packages/django/db/backends/base/base.py", line 282, in ensure_connection
    self.connect()
  File "/home/an/python3.9.12/lib/python3.9/site-packages/django/db/utils.py", line 91, in __exit__
    raise dj_exc_value.with_traceback(traceback) from exc_value
  File "/home/an/python3.9.12/lib/python3.9/site-packages/django/db/backends/base/base.py", line 282, in ensure_connection
    self.connect()
  File "/home/an/python3.9.12/lib/python3.9/site-packages/django/utils/asyncio.py", line 26, in inner
    return func(*args, **kwargs)
  File "/home/an/python3.9.12/lib/python3.9/site-packages/django/db/backends/base/base.py", line 263, in connect
    self.connection = self.get_new_connection(conn_params)
  File "/home/an/python3.9.12/lib/python3.9/site-packages/django/utils/asyncio.py", line 26, in inner
    return func(*args, **kwargs)
  File "/home/an/python3.9.12/lib/python3.9/site-packages/django/db/backends/mysql/base.py", line 247, in get_new_connection
    connection = Database.connect(**conn_params)
  File "/home/an/python3.9.12/lib/python3.9/site-packages/pymysql/connections.py", line 353, in __init__
    self.connect()
  File "/home/an/python3.9.12/lib/python3.9/site-packages/pymysql/connections.py", line 664, in connect
    raise exc
django.db.utils.OperationalError: (2003, "Can't connect to MySQL server on '101.42.5.22' (timed out)")
[2024-01-10 08:59:00,869] [log.py:241] [log:log_response] [ERROR]- Internal Server Error: /api/gtimg/
Traceback (most recent call last):
  File "/home/an/python3.9.12/lib/python3.9/site-packages/pymysql/connections.py", line 613, in connect
    sock = socket.create_connection(
  File "/home/an/python3.9.12/lib/python3.9/socket.py", line 844, in create_connection
    raise err
  File "/home/an/python3.9.12/lib/python3.9/socket.py", line 832, in create_connection
    sock.connect(sa)
socket.timeout: timed out

During handling of the above exception, another exception occurred:

Traceback (most recent call last):
  File "/home/an/python3.9.12/lib/python3.9/site-packages/django/db/backends/base/base.py", line 282, in ensure_connection
    self.connect()
  File "/home/an/python3.9.12/lib/python3.9/site-packages/django/utils/asyncio.py", line 26, in inner
    return func(*args, **kwargs)
  File "/home/an/python3.9.12/lib/python3.9/site-packages/django/db/backends/base/base.py", line 263, in connect
    self.connection = self.get_new_connection(conn_params)
  File "/home/an/python3.9.12/lib/python3.9/site-packages/django/utils/asyncio.py", line 26, in inner
    return func(*args, **kwargs)
  File "/home/an/python3.9.12/lib/python3.9/site-packages/django/db/backends/mysql/base.py", line 247, in get_new_connection
    connection = Database.connect(**conn_params)
  File "/home/an/python3.9.12/lib/python3.9/site-packages/pymysql/connections.py", line 353, in __init__
    self.connect()
  File "/home/an/python3.9.12/lib/python3.9/site-packages/pymysql/connections.py", line 664, in connect
    raise exc
pymysql.err.OperationalError: (2003, "Can't connect to MySQL server on '101.42.5.22' (timed out)")

The above exception was the direct cause of the following exception:

Traceback (most recent call last):
  File "/home/an/python3.9.12/lib/python3.9/site-packages/django/core/handlers/exception.py", line 55, in inner
    response = get_response(request)
  File "/home/an/python3.9.12/lib/python3.9/site-packages/django/utils/deprecation.py", line 138, in __call__
    response = self.process_response(request, response)
  File "/home/an/python3.9.12/lib/python3.9/site-packages/django/contrib/sessions/middleware.py", line 59, in process_response
    request.session.save()
  File "/home/an/python3.9.12/lib/python3.9/site-packages/django/contrib/sessions/backends/db.py", line 80, in save
    return self.create()
  File "/home/an/python3.9.12/lib/python3.9/site-packages/django/contrib/sessions/backends/db.py", line 50, in create
    self._session_key = self._get_new_session_key()
  File "/home/an/python3.9.12/lib/python3.9/site-packages/django/contrib/sessions/backends/base.py", line 150, in _get_new_session_key
    if not self.exists(session_key):
  File "/home/an/python3.9.12/lib/python3.9/site-packages/django/contrib/sessions/backends/db.py", line 46, in exists
    return self.model.objects.filter(session_key=session_key).exists()
  File "/home/an/python3.9.12/lib/python3.9/site-packages/django/db/models/query.py", line 1226, in exists
    return self.query.has_results(using=self.db)
  File "/home/an/python3.9.12/lib/python3.9/site-packages/django/db/models/sql/query.py", line 592, in has_results
    return compiler.has_results()
  File "/home/an/python3.9.12/lib/python3.9/site-packages/django/db/models/sql/compiler.py", line 1366, in has_results
    return bool(self.execute_sql(SINGLE))
  File "/home/an/python3.9.12/lib/python3.9/site-packages/django/db/models/sql/compiler.py", line 1396, in execute_sql
    cursor = self.connection.cursor()
  File "/home/an/python3.9.12/lib/python3.9/site-packages/django/utils/asyncio.py", line 26, in inner
    return func(*args, **kwargs)
  File "/home/an/python3.9.12/lib/python3.9/site-packages/django/db/backends/base/base.py", line 323, in cursor
    return self._cursor()
  File "/home/an/python3.9.12/lib/python3.9/site-packages/django/db/backends/base/base.py", line 299, in _cursor
    self.ensure_connection()
  File "/home/an/python3.9.12/lib/python3.9/site-packages/django/utils/asyncio.py", line 26, in inner
    return func(*args, **kwargs)
  File "/home/an/python3.9.12/lib/python3.9/site-packages/django/db/backends/base/base.py", line 282, in ensure_connection
    self.connect()
  File "/home/an/python3.9.12/lib/python3.9/site-packages/django/db/utils.py", line 91, in __exit__
    raise dj_exc_value.with_traceback(traceback) from exc_value
  File "/home/an/python3.9.12/lib/python3.9/site-packages/django/db/backends/base/base.py", line 282, in ensure_connection
    self.connect()
  File "/home/an/python3.9.12/lib/python3.9/site-packages/django/utils/asyncio.py", line 26, in inner
    return func(*args, **kwargs)
  File "/home/an/python3.9.12/lib/python3.9/site-packages/django/db/backends/base/base.py", line 263, in connect
    self.connection = self.get_new_connection(conn_params)
  File "/home/an/python3.9.12/lib/python3.9/site-packages/django/utils/asyncio.py", line 26, in inner
    return func(*args, **kwargs)
  File "/home/an/python3.9.12/lib/python3.9/site-packages/django/db/backends/mysql/base.py", line 247, in get_new_connection
    connection = Database.connect(**conn_params)
  File "/home/an/python3.9.12/lib/python3.9/site-packages/pymysql/connections.py", line 353, in __init__
    self.connect()
  File "/home/an/python3.9.12/lib/python3.9/site-packages/pymysql/connections.py", line 664, in connect
    raise exc
django.db.utils.OperationalError: (2003, "Can't connect to MySQL server on '101.42.5.22' (timed out)")
[2024-01-10 08:59:00,995] [log.py:241] [log:log_response] [ERROR]- Internal Server Error: /api/gtimg/
Traceback (most recent call last):
  File "/home/an/python3.9.12/lib/python3.9/site-packages/pymysql/connections.py", line 613, in connect
    sock = socket.create_connection(
  File "/home/an/python3.9.12/lib/python3.9/socket.py", line 844, in create_connection
    raise err
  File "/home/an/python3.9.12/lib/python3.9/socket.py", line 832, in create_connection
    sock.connect(sa)
socket.timeout: timed out

During handling of the above exception, another exception occurred:

Traceback (most recent call last):
  File "/home/an/python3.9.12/lib/python3.9/site-packages/django/db/backends/base/base.py", line 282, in ensure_connection
    self.connect()
  File "/home/an/python3.9.12/lib/python3.9/site-packages/django/utils/asyncio.py", line 26, in inner
    return func(*args, **kwargs)
  File "/home/an/python3.9.12/lib/python3.9/site-packages/django/db/backends/base/base.py", line 263, in connect
    self.connection = self.get_new_connection(conn_params)
  File "/home/an/python3.9.12/lib/python3.9/site-packages/django/utils/asyncio.py", line 26, in inner
    return func(*args, **kwargs)
  File "/home/an/python3.9.12/lib/python3.9/site-packages/django/db/backends/mysql/base.py", line 247, in get_new_connection
    connection = Database.connect(**conn_params)
  File "/home/an/python3.9.12/lib/python3.9/site-packages/pymysql/connections.py", line 353, in __init__
    self.connect()
  File "/home/an/python3.9.12/lib/python3.9/site-packages/pymysql/connections.py", line 664, in connect
    raise exc
pymysql.err.OperationalError: (2003, "Can't connect to MySQL server on '101.42.5.22' (timed out)")

The above exception was the direct cause of the following exception:

Traceback (most recent call last):
  File "/home/an/python3.9.12/lib/python3.9/site-packages/django/core/handlers/exception.py", line 55, in inner
    response = get_response(request)
  File "/home/an/python3.9.12/lib/python3.9/site-packages/django/utils/deprecation.py", line 138, in __call__
    response = self.process_response(request, response)
  File "/home/an/python3.9.12/lib/python3.9/site-packages/django/contrib/sessions/middleware.py", line 59, in process_response
    request.session.save()
  File "/home/an/python3.9.12/lib/python3.9/site-packages/django/contrib/sessions/backends/db.py", line 80, in save
    return self.create()
  File "/home/an/python3.9.12/lib/python3.9/site-packages/django/contrib/sessions/backends/db.py", line 50, in create
    self._session_key = self._get_new_session_key()
  File "/home/an/python3.9.12/lib/python3.9/site-packages/django/contrib/sessions/backends/base.py", line 150, in _get_new_session_key
    if not self.exists(session_key):
  File "/home/an/python3.9.12/lib/python3.9/site-packages/django/contrib/sessions/backends/db.py", line 46, in exists
    return self.model.objects.filter(session_key=session_key).exists()
  File "/home/an/python3.9.12/lib/python3.9/site-packages/django/db/models/query.py", line 1226, in exists
    return self.query.has_results(using=self.db)
  File "/home/an/python3.9.12/lib/python3.9/site-packages/django/db/models/sql/query.py", line 592, in has_results
    return compiler.has_results()
  File "/home/an/python3.9.12/lib/python3.9/site-packages/django/db/models/sql/compiler.py", line 1366, in has_results
    return bool(self.execute_sql(SINGLE))
  File "/home/an/python3.9.12/lib/python3.9/site-packages/django/db/models/sql/compiler.py", line 1396, in execute_sql
    cursor = self.connection.cursor()
  File "/home/an/python3.9.12/lib/python3.9/site-packages/django/utils/asyncio.py", line 26, in inner
    return func(*args, **kwargs)
  File "/home/an/python3.9.12/lib/python3.9/site-packages/django/db/backends/base/base.py", line 323, in cursor
    return self._cursor()
  File "/home/an/python3.9.12/lib/python3.9/site-packages/django/db/backends/base/base.py", line 299, in _cursor
    self.ensure_connection()
  File "/home/an/python3.9.12/lib/python3.9/site-packages/django/utils/asyncio.py", line 26, in inner
    return func(*args, **kwargs)
  File "/home/an/python3.9.12/lib/python3.9/site-packages/django/db/backends/base/base.py", line 282, in ensure_connection
    self.connect()
  File "/home/an/python3.9.12/lib/python3.9/site-packages/django/db/utils.py", line 91, in __exit__
    raise dj_exc_value.with_traceback(traceback) from exc_value
  File "/home/an/python3.9.12/lib/python3.9/site-packages/django/db/backends/base/base.py", line 282, in ensure_connection
    self.connect()
  File "/home/an/python3.9.12/lib/python3.9/site-packages/django/utils/asyncio.py", line 26, in inner
    return func(*args, **kwargs)
  File "/home/an/python3.9.12/lib/python3.9/site-packages/django/db/backends/base/base.py", line 263, in connect
    self.connection = self.get_new_connection(conn_params)
  File "/home/an/python3.9.12/lib/python3.9/site-packages/django/utils/asyncio.py", line 26, in inner
    return func(*args, **kwargs)
  File "/home/an/python3.9.12/lib/python3.9/site-packages/django/db/backends/mysql/base.py", line 247, in get_new_connection
    connection = Database.connect(**conn_params)
  File "/home/an/python3.9.12/lib/python3.9/site-packages/pymysql/connections.py", line 353, in __init__
    self.connect()
  File "/home/an/python3.9.12/lib/python3.9/site-packages/pymysql/connections.py", line 664, in connect
    raise exc
django.db.utils.OperationalError: (2003, "Can't connect to MySQL server on '101.42.5.22' (timed out)")
[2024-01-10 08:59:01,295] [log.py:241] [log:log_response] [ERROR]- Internal Server Error: /api/gtimg/
Traceback (most recent call last):
  File "/home/an/python3.9.12/lib/python3.9/site-packages/pymysql/connections.py", line 613, in connect
    sock = socket.create_connection(
  File "/home/an/python3.9.12/lib/python3.9/socket.py", line 844, in create_connection
    raise err
  File "/home/an/python3.9.12/lib/python3.9/socket.py", line 832, in create_connection
    sock.connect(sa)
socket.timeout: timed out

During handling of the above exception, another exception occurred:

Traceback (most recent call last):
  File "/home/an/python3.9.12/lib/python3.9/site-packages/django/db/backends/base/base.py", line 282, in ensure_connection
    self.connect()
  File "/home/an/python3.9.12/lib/python3.9/site-packages/django/utils/asyncio.py", line 26, in inner
    return func(*args, **kwargs)
  File "/home/an/python3.9.12/lib/python3.9/site-packages/django/db/backends/base/base.py", line 263, in connect
    self.connection = self.get_new_connection(conn_params)
  File "/home/an/python3.9.12/lib/python3.9/site-packages/django/utils/asyncio.py", line 26, in inner
    return func(*args, **kwargs)
  File "/home/an/python3.9.12/lib/python3.9/site-packages/django/db/backends/mysql/base.py", line 247, in get_new_connection
    connection = Database.connect(**conn_params)
  File "/home/an/python3.9.12/lib/python3.9/site-packages/pymysql/connections.py", line 353, in __init__
    self.connect()
  File "/home/an/python3.9.12/lib/python3.9/site-packages/pymysql/connections.py", line 664, in connect
    raise exc
pymysql.err.OperationalError: (2003, "Can't connect to MySQL server on '101.42.5.22' (timed out)")

The above exception was the direct cause of the following exception:

Traceback (most recent call last):
  File "/home/an/python3.9.12/lib/python3.9/site-packages/django/core/handlers/exception.py", line 55, in inner
    response = get_response(request)
  File "/home/an/python3.9.12/lib/python3.9/site-packages/django/utils/deprecation.py", line 138, in __call__
    response = self.process_response(request, response)
  File "/home/an/python3.9.12/lib/python3.9/site-packages/django/contrib/sessions/middleware.py", line 59, in process_response
    request.session.save()
  File "/home/an/python3.9.12/lib/python3.9/site-packages/django/contrib/sessions/backends/db.py", line 80, in save
    return self.create()
  File "/home/an/python3.9.12/lib/python3.9/site-packages/django/contrib/sessions/backends/db.py", line 50, in create
    self._session_key = self._get_new_session_key()
  File "/home/an/python3.9.12/lib/python3.9/site-packages/django/contrib/sessions/backends/base.py", line 150, in _get_new_session_key
    if not self.exists(session_key):
  File "/home/an/python3.9.12/lib/python3.9/site-packages/django/contrib/sessions/backends/db.py", line 46, in exists
    return self.model.objects.filter(session_key=session_key).exists()
  File "/home/an/python3.9.12/lib/python3.9/site-packages/django/db/models/query.py", line 1226, in exists
    return self.query.has_results(using=self.db)
  File "/home/an/python3.9.12/lib/python3.9/site-packages/django/db/models/sql/query.py", line 592, in has_results
    return compiler.has_results()
  File "/home/an/python3.9.12/lib/python3.9/site-packages/django/db/models/sql/compiler.py", line 1366, in has_results
    return bool(self.execute_sql(SINGLE))
  File "/home/an/python3.9.12/lib/python3.9/site-packages/django/db/models/sql/compiler.py", line 1396, in execute_sql
    cursor = self.connection.cursor()
  File "/home/an/python3.9.12/lib/python3.9/site-packages/django/utils/asyncio.py", line 26, in inner
    return func(*args, **kwargs)
  File "/home/an/python3.9.12/lib/python3.9/site-packages/django/db/backends/base/base.py", line 323, in cursor
    return self._cursor()
  File "/home/an/python3.9.12/lib/python3.9/site-packages/django/db/backends/base/base.py", line 299, in _cursor
    self.ensure_connection()
  File "/home/an/python3.9.12/lib/python3.9/site-packages/django/utils/asyncio.py", line 26, in inner
    return func(*args, **kwargs)
  File "/home/an/python3.9.12/lib/python3.9/site-packages/django/db/backends/base/base.py", line 282, in ensure_connection
    self.connect()
  File "/home/an/python3.9.12/lib/python3.9/site-packages/django/db/utils.py", line 91, in __exit__
    raise dj_exc_value.with_traceback(traceback) from exc_value
  File "/home/an/python3.9.12/lib/python3.9/site-packages/django/db/backends/base/base.py", line 282, in ensure_connection
    self.connect()
  File "/home/an/python3.9.12/lib/python3.9/site-packages/django/utils/asyncio.py", line 26, in inner
    return func(*args, **kwargs)
  File "/home/an/python3.9.12/lib/python3.9/site-packages/django/db/backends/base/base.py", line 263, in connect
    self.connection = self.get_new_connection(conn_params)
  File "/home/an/python3.9.12/lib/python3.9/site-packages/django/utils/asyncio.py", line 26, in inner
    return func(*args, **kwargs)
  File "/home/an/python3.9.12/lib/python3.9/site-packages/django/db/backends/mysql/base.py", line 247, in get_new_connection
    connection = Database.connect(**conn_params)
  File "/home/an/python3.9.12/lib/python3.9/site-packages/pymysql/connections.py", line 353, in __init__
    self.connect()
  File "/home/an/python3.9.12/lib/python3.9/site-packages/pymysql/connections.py", line 664, in connect
    raise exc
django.db.utils.OperationalError: (2003, "Can't connect to MySQL server on '101.42.5.22' (timed out)")
