[2023-11-27 18:51:49,116] [exception.py:124] [exception:response_for_exception] [ERROR]- Invalid HTTP_HOST header: 'ar.hz.netease.com:443ar.hz.netease.com:443'. The domain name provided is not valid according to RFC 1034/1035.
Traceback (most recent call last):
  File "/home/an/python_examin/lib/python3.9/site-packages/django/core/handlers/exception.py", line 55, in inner
    response = get_response(request)
  File "/home/an/python_examin/lib/python3.9/site-packages/django/utils/deprecation.py", line 135, in __call__
    response = self.process_request(request)
  File "/home/an/python_examin/lib/python3.9/site-packages/django/middleware/common.py", line 48, in process_request
    host = request.get_host()
  File "/home/an/python_examin/lib/python3.9/site-packages/django/http/request.py", line 148, in get_host
    raise DisallowedHost(msg)
django.core.exceptions.DisallowedHost: Invalid HTTP_HOST header: 'ar.hz.netease.com:443ar.hz.netease.com:443'. The domain name provided is not valid according to RFC 1034/1035.
[2023-11-28 13:41:37,700] [exception.py:124] [exception:response_for_exception] [ERROR]- Invalid HTTP_HOST header: 'ar.hz.netease.com:443ar.hz.netease.com:443'. The domain name provided is not valid according to RFC 1034/1035.
Traceback (most recent call last):
  File "/home/an/python_examin/lib/python3.9/site-packages/django/core/handlers/exception.py", line 55, in inner
    response = get_response(request)
  File "/home/an/python_examin/lib/python3.9/site-packages/django/utils/deprecation.py", line 135, in __call__
    response = self.process_request(request)
  File "/home/an/python_examin/lib/python3.9/site-packages/django/middleware/common.py", line 48, in process_request
    host = request.get_host()
  File "/home/an/python_examin/lib/python3.9/site-packages/django/http/request.py", line 148, in get_host
    raise DisallowedHost(msg)
django.core.exceptions.DisallowedHost: Invalid HTTP_HOST header: 'ar.hz.netease.com:443ar.hz.netease.com:443'. The domain name provided is not valid according to RFC 1034/1035.
[2023-11-29 01:19:57,622] [exception.py:124] [exception:response_for_exception] [ERROR]- Invalid HTTP_HOST header: 'ar.hz.netease.com:443ar.hz.netease.com:443'. The domain name provided is not valid according to RFC 1034/1035.
Traceback (most recent call last):
  File "/home/an/python_examin/lib/python3.9/site-packages/django/core/handlers/exception.py", line 55, in inner
    response = get_response(request)
  File "/home/an/python_examin/lib/python3.9/site-packages/django/utils/deprecation.py", line 135, in __call__
    response = self.process_request(request)
  File "/home/an/python_examin/lib/python3.9/site-packages/django/middleware/common.py", line 48, in process_request
    host = request.get_host()
  File "/home/an/python_examin/lib/python3.9/site-packages/django/http/request.py", line 148, in get_host
    raise DisallowedHost(msg)
django.core.exceptions.DisallowedHost: Invalid HTTP_HOST header: 'ar.hz.netease.com:443ar.hz.netease.com:443'. The domain name provided is not valid according to RFC 1034/1035.
[2023-11-29 04:06:53,438] [exception.py:124] [exception:response_for_exception] [ERROR]- Invalid HTTP_HOST header: 'ar.hz.netease.com:443ar.hz.netease.com:443'. The domain name provided is not valid according to RFC 1034/1035.
Traceback (most recent call last):
  File "/home/an/python_examin/lib/python3.9/site-packages/django/core/handlers/exception.py", line 55, in inner
    response = get_response(request)
  File "/home/an/python_examin/lib/python3.9/site-packages/django/utils/deprecation.py", line 135, in __call__
    response = self.process_request(request)
  File "/home/an/python_examin/lib/python3.9/site-packages/django/middleware/common.py", line 48, in process_request
    host = request.get_host()
  File "/home/an/python_examin/lib/python3.9/site-packages/django/http/request.py", line 148, in get_host
    raise DisallowedHost(msg)
django.core.exceptions.DisallowedHost: Invalid HTTP_HOST header: 'ar.hz.netease.com:443ar.hz.netease.com:443'. The domain name provided is not valid according to RFC 1034/1035.
[2023-12-04 04:23:40,624] [log.py:241] [log:log_response] [ERROR]- Internal Server Error: /api/getxx/
Traceback (most recent call last):
  File "/home/an/python_examin/lib/python3.9/site-packages/django/core/handlers/exception.py", line 55, in inner
    response = get_response(request)
  File "/home/an/python_examin/lib/python3.9/site-packages/django/core/handlers/base.py", line 197, in _get_response
    response = wrapped_callback(request, *callback_args, **callback_kwargs)
  File "./StudentExamination/views.py", line 249, in get_Logistic
    data = data["data"]["track_info"]["tracking"]["providers"][0]["events"]
KeyError: 'track_info'
[2023-12-04 04:33:40,798] [log.py:241] [log:log_response] [ERROR]- Internal Server Error: /api/getxx/
Traceback (most recent call last):
  File "/home/an/python_examin/lib/python3.9/site-packages/django/core/handlers/exception.py", line 55, in inner
    response = get_response(request)
  File "/home/an/python_examin/lib/python3.9/site-packages/django/core/handlers/base.py", line 197, in _get_response
    response = wrapped_callback(request, *callback_args, **callback_kwargs)
  File "./StudentExamination/views.py", line 249, in get_Logistic
    data = data["data"]["track_info"]["tracking"]["providers"][0]["events"]
KeyError: 'track_info'
[2023-12-04 04:53:40,898] [log.py:241] [log:log_response] [ERROR]- Internal Server Error: /api/getxx/
Traceback (most recent call last):
  File "/home/an/python_examin/lib/python3.9/site-packages/django/core/handlers/exception.py", line 55, in inner
    response = get_response(request)
  File "/home/an/python_examin/lib/python3.9/site-packages/django/core/handlers/base.py", line 197, in _get_response
    response = wrapped_callback(request, *callback_args, **callback_kwargs)
  File "./StudentExamination/views.py", line 249, in get_Logistic
    data = data["data"]["track_info"]["tracking"]["providers"][0]["events"]
KeyError: 'track_info'
[2023-12-04 05:23:40,986] [log.py:241] [log:log_response] [ERROR]- Internal Server Error: /api/getxx/
Traceback (most recent call last):
  File "/home/an/python_examin/lib/python3.9/site-packages/django/core/handlers/exception.py", line 55, in inner
    response = get_response(request)
  File "/home/an/python_examin/lib/python3.9/site-packages/django/core/handlers/base.py", line 197, in _get_response
    response = wrapped_callback(request, *callback_args, **callback_kwargs)
  File "./StudentExamination/views.py", line 249, in get_Logistic
    data = data["data"]["track_info"]["tracking"]["providers"][0]["events"]
KeyError: 'track_info'
