[2023-12-28 11:48:53,612] [log.py:241] [log:log_response] [ERROR]- Internal Server Error: /api/getxx/
Traceback (most recent call last):
  File "/home/an/python_examin/lib/python3.9/site-packages/django/core/handlers/exception.py", line 55, in inner
    response = get_response(request)
  File "/home/an/python_examin/lib/python3.9/site-packages/django/core/handlers/base.py", line 197, in _get_response
    response = wrapped_callback(request, *callback_args, **callback_kwargs)
  File "./StudentExamination/views.py", line 296, in get_Logistic
    data_dict[data[i]["time_raw"]["date"] + "_" + data[i]["time_raw"]["time"]] = data[i]["description"] + " " + \
TypeError: can only concatenate str (not "NoneType") to str
[2023-12-28 11:50:54,181] [log.py:241] [log:log_response] [ERROR]- Internal Server Error: /api/getxx/
Traceback (most recent call last):
  File "/home/an/python_examin/lib/python3.9/site-packages/django/core/handlers/exception.py", line 55, in inner
    response = get_response(request)
  File "/home/an/python_examin/lib/python3.9/site-packages/django/core/handlers/base.py", line 197, in _get_response
    response = wrapped_callback(request, *callback_args, **callback_kwargs)
  File "./StudentExamination/views.py", line 296, in get_Logistic
    data_dict[data[i]["time_raw"]["date"] + "_" + data[i]["time_raw"]["time"]] = data[i]["description"] + " " + \
TypeError: can only concatenate str (not "NoneType") to str
[2023-12-28 11:58:53,744] [log.py:241] [log:log_response] [ERROR]- Internal Server Error: /api/getxx/
Traceback (most recent call last):
  File "/home/an/python_examin/lib/python3.9/site-packages/django/core/handlers/exception.py", line 55, in inner
    response = get_response(request)
  File "/home/an/python_examin/lib/python3.9/site-packages/django/core/handlers/base.py", line 197, in _get_response
    response = wrapped_callback(request, *callback_args, **callback_kwargs)
  File "./StudentExamination/views.py", line 296, in get_Logistic
    data_dict[data[i]["time_raw"]["date"] + "_" + data[i]["time_raw"]["time"]] = data[i]["description"] + " " + \
TypeError: can only concatenate str (not "NoneType") to str
[2023-12-28 12:00:54,278] [log.py:241] [log:log_response] [ERROR]- Internal Server Error: /api/getxx/
Traceback (most recent call last):
  File "/home/an/python_examin/lib/python3.9/site-packages/django/core/handlers/exception.py", line 55, in inner
    response = get_response(request)
  File "/home/an/python_examin/lib/python3.9/site-packages/django/core/handlers/base.py", line 197, in _get_response
    response = wrapped_callback(request, *callback_args, **callback_kwargs)
  File "./StudentExamination/views.py", line 296, in get_Logistic
    data_dict[data[i]["time_raw"]["date"] + "_" + data[i]["time_raw"]["time"]] = data[i]["description"] + " " + \
TypeError: can only concatenate str (not "NoneType") to str
[2023-12-28 12:18:53,839] [log.py:241] [log:log_response] [ERROR]- Internal Server Error: /api/getxx/
Traceback (most recent call last):
  File "/home/an/python_examin/lib/python3.9/site-packages/django/core/handlers/exception.py", line 55, in inner
    response = get_response(request)
  File "/home/an/python_examin/lib/python3.9/site-packages/django/core/handlers/base.py", line 197, in _get_response
    response = wrapped_callback(request, *callback_args, **callback_kwargs)
  File "./StudentExamination/views.py", line 296, in get_Logistic
    data_dict[data[i]["time_raw"]["date"] + "_" + data[i]["time_raw"]["time"]] = data[i]["description"] + " " + \
TypeError: can only concatenate str (not "NoneType") to str
[2023-12-28 12:20:54,371] [log.py:241] [log:log_response] [ERROR]- Internal Server Error: /api/getxx/
Traceback (most recent call last):
  File "/home/an/python_examin/lib/python3.9/site-packages/django/core/handlers/exception.py", line 55, in inner
    response = get_response(request)
  File "/home/an/python_examin/lib/python3.9/site-packages/django/core/handlers/base.py", line 197, in _get_response
    response = wrapped_callback(request, *callback_args, **callback_kwargs)
  File "./StudentExamination/views.py", line 296, in get_Logistic
    data_dict[data[i]["time_raw"]["date"] + "_" + data[i]["time_raw"]["time"]] = data[i]["description"] + " " + \
TypeError: can only concatenate str (not "NoneType") to str
[2023-12-28 12:48:53,941] [log.py:241] [log:log_response] [ERROR]- Internal Server Error: /api/getxx/
Traceback (most recent call last):
  File "/home/an/python_examin/lib/python3.9/site-packages/django/core/handlers/exception.py", line 55, in inner
    response = get_response(request)
  File "/home/an/python_examin/lib/python3.9/site-packages/django/core/handlers/base.py", line 197, in _get_response
    response = wrapped_callback(request, *callback_args, **callback_kwargs)
  File "./StudentExamination/views.py", line 296, in get_Logistic
    data_dict[data[i]["time_raw"]["date"] + "_" + data[i]["time_raw"]["time"]] = data[i]["description"] + " " + \
TypeError: can only concatenate str (not "NoneType") to str
[2023-12-28 12:50:54,476] [log.py:241] [log:log_response] [ERROR]- Internal Server Error: /api/getxx/
Traceback (most recent call last):
  File "/home/an/python_examin/lib/python3.9/site-packages/django/core/handlers/exception.py", line 55, in inner
    response = get_response(request)
  File "/home/an/python_examin/lib/python3.9/site-packages/django/core/handlers/base.py", line 197, in _get_response
    response = wrapped_callback(request, *callback_args, **callback_kwargs)
  File "./StudentExamination/views.py", line 296, in get_Logistic
    data_dict[data[i]["time_raw"]["date"] + "_" + data[i]["time_raw"]["time"]] = data[i]["description"] + " " + \
TypeError: can only concatenate str (not "NoneType") to str
[2023-12-29 11:57:54,404] [log.py:241] [log:log_response] [ERROR]- Internal Server Error: /api/getxx/
Traceback (most recent call last):
  File "/home/an/python_examin/lib/python3.9/site-packages/django/core/handlers/exception.py", line 55, in inner
    response = get_response(request)
  File "/home/an/python_examin/lib/python3.9/site-packages/django/core/handlers/base.py", line 197, in _get_response
    response = wrapped_callback(request, *callback_args, **callback_kwargs)
  File "./StudentExamination/views.py", line 296, in get_Logistic
    data_dict[data[i]["time_raw"]["date"] + "_" + data[i]["time_raw"]["time"]] = data[i]["description"] + " " + \
TypeError: can only concatenate str (not "NoneType") to str
[2023-12-29 11:59:54,822] [log.py:241] [log:log_response] [ERROR]- Internal Server Error: /api/getxx/
Traceback (most recent call last):
  File "/home/an/python_examin/lib/python3.9/site-packages/django/core/handlers/exception.py", line 55, in inner
    response = get_response(request)
  File "/home/an/python_examin/lib/python3.9/site-packages/django/core/handlers/base.py", line 197, in _get_response
    response = wrapped_callback(request, *callback_args, **callback_kwargs)
  File "./StudentExamination/views.py", line 296, in get_Logistic
    data_dict[data[i]["time_raw"]["date"] + "_" + data[i]["time_raw"]["time"]] = data[i]["description"] + " " + \
TypeError: can only concatenate str (not "NoneType") to str
[2023-12-29 12:07:54,515] [log.py:241] [log:log_response] [ERROR]- Internal Server Error: /api/getxx/
Traceback (most recent call last):
  File "/home/an/python_examin/lib/python3.9/site-packages/django/core/handlers/exception.py", line 55, in inner
    response = get_response(request)
  File "/home/an/python_examin/lib/python3.9/site-packages/django/core/handlers/base.py", line 197, in _get_response
    response = wrapped_callback(request, *callback_args, **callback_kwargs)
  File "./StudentExamination/views.py", line 296, in get_Logistic
    data_dict[data[i]["time_raw"]["date"] + "_" + data[i]["time_raw"]["time"]] = data[i]["description"] + " " + \
TypeError: can only concatenate str (not "NoneType") to str
[2023-12-29 12:09:54,915] [log.py:241] [log:log_response] [ERROR]- Internal Server Error: /api/getxx/
Traceback (most recent call last):
  File "/home/an/python_examin/lib/python3.9/site-packages/django/core/handlers/exception.py", line 55, in inner
    response = get_response(request)
  File "/home/an/python_examin/lib/python3.9/site-packages/django/core/handlers/base.py", line 197, in _get_response
    response = wrapped_callback(request, *callback_args, **callback_kwargs)
  File "./StudentExamination/views.py", line 296, in get_Logistic
    data_dict[data[i]["time_raw"]["date"] + "_" + data[i]["time_raw"]["time"]] = data[i]["description"] + " " + \
TypeError: can only concatenate str (not "NoneType") to str
[2023-12-29 12:27:54,606] [log.py:241] [log:log_response] [ERROR]- Internal Server Error: /api/getxx/
Traceback (most recent call last):
  File "/home/an/python_examin/lib/python3.9/site-packages/django/core/handlers/exception.py", line 55, in inner
    response = get_response(request)
  File "/home/an/python_examin/lib/python3.9/site-packages/django/core/handlers/base.py", line 197, in _get_response
    response = wrapped_callback(request, *callback_args, **callback_kwargs)
  File "./StudentExamination/views.py", line 296, in get_Logistic
    data_dict[data[i]["time_raw"]["date"] + "_" + data[i]["time_raw"]["time"]] = data[i]["description"] + " " + \
TypeError: can only concatenate str (not "NoneType") to str
[2023-12-29 12:29:55,009] [log.py:241] [log:log_response] [ERROR]- Internal Server Error: /api/getxx/
Traceback (most recent call last):
  File "/home/an/python_examin/lib/python3.9/site-packages/django/core/handlers/exception.py", line 55, in inner
    response = get_response(request)
  File "/home/an/python_examin/lib/python3.9/site-packages/django/core/handlers/base.py", line 197, in _get_response
    response = wrapped_callback(request, *callback_args, **callback_kwargs)
  File "./StudentExamination/views.py", line 296, in get_Logistic
    data_dict[data[i]["time_raw"]["date"] + "_" + data[i]["time_raw"]["time"]] = data[i]["description"] + " " + \
TypeError: can only concatenate str (not "NoneType") to str
[2023-12-29 12:57:54,719] [log.py:241] [log:log_response] [ERROR]- Internal Server Error: /api/getxx/
Traceback (most recent call last):
  File "/home/an/python_examin/lib/python3.9/site-packages/django/core/handlers/exception.py", line 55, in inner
    response = get_response(request)
  File "/home/an/python_examin/lib/python3.9/site-packages/django/core/handlers/base.py", line 197, in _get_response
    response = wrapped_callback(request, *callback_args, **callback_kwargs)
  File "./StudentExamination/views.py", line 296, in get_Logistic
    data_dict[data[i]["time_raw"]["date"] + "_" + data[i]["time_raw"]["time"]] = data[i]["description"] + " " + \
TypeError: can only concatenate str (not "NoneType") to str
[2023-12-29 12:59:55,098] [log.py:241] [log:log_response] [ERROR]- Internal Server Error: /api/getxx/
Traceback (most recent call last):
  File "/home/an/python_examin/lib/python3.9/site-packages/django/core/handlers/exception.py", line 55, in inner
    response = get_response(request)
  File "/home/an/python_examin/lib/python3.9/site-packages/django/core/handlers/base.py", line 197, in _get_response
    response = wrapped_callback(request, *callback_args, **callback_kwargs)
  File "./StudentExamination/views.py", line 296, in get_Logistic
    data_dict[data[i]["time_raw"]["date"] + "_" + data[i]["time_raw"]["time"]] = data[i]["description"] + " " + \
TypeError: can only concatenate str (not "NoneType") to str
[2023-12-30 12:06:37,925] [log.py:241] [log:log_response] [ERROR]- Internal Server Error: /api/getxx/
Traceback (most recent call last):
  File "/home/an/python_examin/lib/python3.9/site-packages/django/core/handlers/exception.py", line 55, in inner
    response = get_response(request)
  File "/home/an/python_examin/lib/python3.9/site-packages/django/core/handlers/base.py", line 197, in _get_response
    response = wrapped_callback(request, *callback_args, **callback_kwargs)
  File "./StudentExamination/views.py", line 296, in get_Logistic
    data_dict[data[i]["time_raw"]["date"] + "_" + data[i]["time_raw"]["time"]] = data[i]["description"] + " " + \
TypeError: can only concatenate str (not "NoneType") to str
[2023-12-30 12:16:38,022] [log.py:241] [log:log_response] [ERROR]- Internal Server Error: /api/getxx/
Traceback (most recent call last):
  File "/home/an/python_examin/lib/python3.9/site-packages/django/core/handlers/exception.py", line 55, in inner
    response = get_response(request)
  File "/home/an/python_examin/lib/python3.9/site-packages/django/core/handlers/base.py", line 197, in _get_response
    response = wrapped_callback(request, *callback_args, **callback_kwargs)
  File "./StudentExamination/views.py", line 296, in get_Logistic
    data_dict[data[i]["time_raw"]["date"] + "_" + data[i]["time_raw"]["time"]] = data[i]["description"] + " " + \
TypeError: can only concatenate str (not "NoneType") to str
[2023-12-30 12:36:38,118] [log.py:241] [log:log_response] [ERROR]- Internal Server Error: /api/getxx/
Traceback (most recent call last):
  File "/home/an/python_examin/lib/python3.9/site-packages/django/core/handlers/exception.py", line 55, in inner
    response = get_response(request)
  File "/home/an/python_examin/lib/python3.9/site-packages/django/core/handlers/base.py", line 197, in _get_response
    response = wrapped_callback(request, *callback_args, **callback_kwargs)
  File "./StudentExamination/views.py", line 296, in get_Logistic
    data_dict[data[i]["time_raw"]["date"] + "_" + data[i]["time_raw"]["time"]] = data[i]["description"] + " " + \
TypeError: can only concatenate str (not "NoneType") to str
[2023-12-30 13:06:38,211] [log.py:241] [log:log_response] [ERROR]- Internal Server Error: /api/getxx/
Traceback (most recent call last):
  File "/home/an/python_examin/lib/python3.9/site-packages/django/core/handlers/exception.py", line 55, in inner
    response = get_response(request)
  File "/home/an/python_examin/lib/python3.9/site-packages/django/core/handlers/base.py", line 197, in _get_response
    response = wrapped_callback(request, *callback_args, **callback_kwargs)
  File "./StudentExamination/views.py", line 296, in get_Logistic
    data_dict[data[i]["time_raw"]["date"] + "_" + data[i]["time_raw"]["time"]] = data[i]["description"] + " " + \
TypeError: can only concatenate str (not "NoneType") to str
[2023-12-31 10:52:14,835] [log.py:241] [log:log_response] [ERROR]- Internal Server Error: /api/getxx/
Traceback (most recent call last):
  File "/home/an/python_examin/lib/python3.9/site-packages/django/core/handlers/exception.py", line 55, in inner
    response = get_response(request)
  File "/home/an/python_examin/lib/python3.9/site-packages/django/core/handlers/base.py", line 197, in _get_response
    response = wrapped_callback(request, *callback_args, **callback_kwargs)
  File "./StudentExamination/views.py", line 293, in get_Logistic
    data = data["data"]["track_info"]["tracking"]["providers"][0]["events"]
KeyError: 'track_info'
[2023-12-31 11:02:14,934] [log.py:241] [log:log_response] [ERROR]- Internal Server Error: /api/getxx/
Traceback (most recent call last):
  File "/home/an/python_examin/lib/python3.9/site-packages/django/core/handlers/exception.py", line 55, in inner
    response = get_response(request)
  File "/home/an/python_examin/lib/python3.9/site-packages/django/core/handlers/base.py", line 197, in _get_response
    response = wrapped_callback(request, *callback_args, **callback_kwargs)
  File "./StudentExamination/views.py", line 293, in get_Logistic
    data = data["data"]["track_info"]["tracking"]["providers"][0]["events"]
KeyError: 'track_info'
[2023-12-31 11:22:15,026] [log.py:241] [log:log_response] [ERROR]- Internal Server Error: /api/getxx/
Traceback (most recent call last):
  File "/home/an/python_examin/lib/python3.9/site-packages/django/core/handlers/exception.py", line 55, in inner
    response = get_response(request)
  File "/home/an/python_examin/lib/python3.9/site-packages/django/core/handlers/base.py", line 197, in _get_response
    response = wrapped_callback(request, *callback_args, **callback_kwargs)
  File "./StudentExamination/views.py", line 293, in get_Logistic
    data = data["data"]["track_info"]["tracking"]["providers"][0]["events"]
KeyError: 'track_info'
[2023-12-31 11:52:15,111] [log.py:241] [log:log_response] [ERROR]- Internal Server Error: /api/getxx/
Traceback (most recent call last):
  File "/home/an/python_examin/lib/python3.9/site-packages/django/core/handlers/exception.py", line 55, in inner
    response = get_response(request)
  File "/home/an/python_examin/lib/python3.9/site-packages/django/core/handlers/base.py", line 197, in _get_response
    response = wrapped_callback(request, *callback_args, **callback_kwargs)
  File "./StudentExamination/views.py", line 293, in get_Logistic
    data = data["data"]["track_info"]["tracking"]["providers"][0]["events"]
KeyError: 'track_info'
[2023-12-31 12:10:03,201] [log.py:241] [log:log_response] [ERROR]- Internal Server Error: /api/getxx/
Traceback (most recent call last):
  File "/home/an/python_examin/lib/python3.9/site-packages/django/core/handlers/exception.py", line 55, in inner
    response = get_response(request)
  File "/home/an/python_examin/lib/python3.9/site-packages/django/core/handlers/base.py", line 197, in _get_response
    response = wrapped_callback(request, *callback_args, **callback_kwargs)
  File "./StudentExamination/views.py", line 296, in get_Logistic
    data_dict[data[i]["time_raw"]["date"] + "_" + data[i]["time_raw"]["time"]] = data[i]["description"] + " " + \
TypeError: can only concatenate str (not "NoneType") to str
[2023-12-31 12:20:03,297] [log.py:241] [log:log_response] [ERROR]- Internal Server Error: /api/getxx/
Traceback (most recent call last):
  File "/home/an/python_examin/lib/python3.9/site-packages/django/core/handlers/exception.py", line 55, in inner
    response = get_response(request)
  File "/home/an/python_examin/lib/python3.9/site-packages/django/core/handlers/base.py", line 197, in _get_response
    response = wrapped_callback(request, *callback_args, **callback_kwargs)
  File "./StudentExamination/views.py", line 296, in get_Logistic
    data_dict[data[i]["time_raw"]["date"] + "_" + data[i]["time_raw"]["time"]] = data[i]["description"] + " " + \
TypeError: can only concatenate str (not "NoneType") to str
[2023-12-31 12:40:03,393] [log.py:241] [log:log_response] [ERROR]- Internal Server Error: /api/getxx/
Traceback (most recent call last):
  File "/home/an/python_examin/lib/python3.9/site-packages/django/core/handlers/exception.py", line 55, in inner
    response = get_response(request)
  File "/home/an/python_examin/lib/python3.9/site-packages/django/core/handlers/base.py", line 197, in _get_response
    response = wrapped_callback(request, *callback_args, **callback_kwargs)
  File "./StudentExamination/views.py", line 296, in get_Logistic
    data_dict[data[i]["time_raw"]["date"] + "_" + data[i]["time_raw"]["time"]] = data[i]["description"] + " " + \
TypeError: can only concatenate str (not "NoneType") to str
[2023-12-31 13:10:03,486] [log.py:241] [log:log_response] [ERROR]- Internal Server Error: /api/getxx/
Traceback (most recent call last):
  File "/home/an/python_examin/lib/python3.9/site-packages/django/core/handlers/exception.py", line 55, in inner
    response = get_response(request)
  File "/home/an/python_examin/lib/python3.9/site-packages/django/core/handlers/base.py", line 197, in _get_response
    response = wrapped_callback(request, *callback_args, **callback_kwargs)
  File "./StudentExamination/views.py", line 296, in get_Logistic
    data_dict[data[i]["time_raw"]["date"] + "_" + data[i]["time_raw"]["time"]] = data[i]["description"] + " " + \
TypeError: can only concatenate str (not "NoneType") to str
[2024-01-01 12:19:34,080] [log.py:241] [log:log_response] [ERROR]- Internal Server Error: /api/getxx/
Traceback (most recent call last):
  File "/home/an/python_examin/lib/python3.9/site-packages/django/core/handlers/exception.py", line 55, in inner
    response = get_response(request)
  File "/home/an/python_examin/lib/python3.9/site-packages/django/core/handlers/base.py", line 197, in _get_response
    response = wrapped_callback(request, *callback_args, **callback_kwargs)
  File "./StudentExamination/views.py", line 296, in get_Logistic
    data_dict[data[i]["time_raw"]["date"] + "_" + data[i]["time_raw"]["time"]] = data[i]["description"] + " " + \
TypeError: can only concatenate str (not "NoneType") to str
[2024-01-01 12:29:34,185] [log.py:241] [log:log_response] [ERROR]- Internal Server Error: /api/getxx/
Traceback (most recent call last):
  File "/home/an/python_examin/lib/python3.9/site-packages/django/core/handlers/exception.py", line 55, in inner
    response = get_response(request)
  File "/home/an/python_examin/lib/python3.9/site-packages/django/core/handlers/base.py", line 197, in _get_response
    response = wrapped_callback(request, *callback_args, **callback_kwargs)
  File "./StudentExamination/views.py", line 296, in get_Logistic
    data_dict[data[i]["time_raw"]["date"] + "_" + data[i]["time_raw"]["time"]] = data[i]["description"] + " " + \
TypeError: can only concatenate str (not "NoneType") to str
[2024-01-01 12:49:34,274] [log.py:241] [log:log_response] [ERROR]- Internal Server Error: /api/getxx/
Traceback (most recent call last):
  File "/home/an/python_examin/lib/python3.9/site-packages/django/core/handlers/exception.py", line 55, in inner
    response = get_response(request)
  File "/home/an/python_examin/lib/python3.9/site-packages/django/core/handlers/base.py", line 197, in _get_response
    response = wrapped_callback(request, *callback_args, **callback_kwargs)
  File "./StudentExamination/views.py", line 296, in get_Logistic
    data_dict[data[i]["time_raw"]["date"] + "_" + data[i]["time_raw"]["time"]] = data[i]["description"] + " " + \
TypeError: can only concatenate str (not "NoneType") to str
[2024-01-01 13:19:34,364] [log.py:241] [log:log_response] [ERROR]- Internal Server Error: /api/getxx/
Traceback (most recent call last):
  File "/home/an/python_examin/lib/python3.9/site-packages/django/core/handlers/exception.py", line 55, in inner
    response = get_response(request)
  File "/home/an/python_examin/lib/python3.9/site-packages/django/core/handlers/base.py", line 197, in _get_response
    response = wrapped_callback(request, *callback_args, **callback_kwargs)
  File "./StudentExamination/views.py", line 296, in get_Logistic
    data_dict[data[i]["time_raw"]["date"] + "_" + data[i]["time_raw"]["time"]] = data[i]["description"] + " " + \
TypeError: can only concatenate str (not "NoneType") to str
[2024-01-02 12:28:05,942] [log.py:241] [log:log_response] [ERROR]- Internal Server Error: /api/getxx/
Traceback (most recent call last):
  File "/home/an/python_examin/lib/python3.9/site-packages/django/core/handlers/exception.py", line 55, in inner
    response = get_response(request)
  File "/home/an/python_examin/lib/python3.9/site-packages/django/core/handlers/base.py", line 197, in _get_response
    response = wrapped_callback(request, *callback_args, **callback_kwargs)
  File "./StudentExamination/views.py", line 293, in get_Logistic
    data = data["data"]["track_info"]["tracking"]["providers"][0]["events"]
KeyError: 'track_info'
[2024-01-02 12:38:06,035] [log.py:241] [log:log_response] [ERROR]- Internal Server Error: /api/getxx/
Traceback (most recent call last):
  File "/home/an/python_examin/lib/python3.9/site-packages/django/core/handlers/exception.py", line 55, in inner
    response = get_response(request)
  File "/home/an/python_examin/lib/python3.9/site-packages/django/core/handlers/base.py", line 197, in _get_response
    response = wrapped_callback(request, *callback_args, **callback_kwargs)
  File "./StudentExamination/views.py", line 293, in get_Logistic
    data = data["data"]["track_info"]["tracking"]["providers"][0]["events"]
KeyError: 'track_info'
[2024-01-02 12:58:06,130] [log.py:241] [log:log_response] [ERROR]- Internal Server Error: /api/getxx/
Traceback (most recent call last):
  File "/home/an/python_examin/lib/python3.9/site-packages/django/core/handlers/exception.py", line 55, in inner
    response = get_response(request)
  File "/home/an/python_examin/lib/python3.9/site-packages/django/core/handlers/base.py", line 197, in _get_response
    response = wrapped_callback(request, *callback_args, **callback_kwargs)
  File "./StudentExamination/views.py", line 293, in get_Logistic
    data = data["data"]["track_info"]["tracking"]["providers"][0]["events"]
KeyError: 'track_info'
[2024-01-02 13:28:06,221] [log.py:241] [log:log_response] [ERROR]- Internal Server Error: /api/getxx/
Traceback (most recent call last):
  File "/home/an/python_examin/lib/python3.9/site-packages/django/core/handlers/exception.py", line 55, in inner
    response = get_response(request)
  File "/home/an/python_examin/lib/python3.9/site-packages/django/core/handlers/base.py", line 197, in _get_response
    response = wrapped_callback(request, *callback_args, **callback_kwargs)
  File "./StudentExamination/views.py", line 293, in get_Logistic
    data = data["data"]["track_info"]["tracking"]["providers"][0]["events"]
KeyError: 'track_info'
[2024-01-04 00:36:27,495] [log.py:241] [log:log_response] [ERROR]- Internal Server Error: /api/getxx/
Traceback (most recent call last):
  File "/home/an/python_examin/lib/python3.9/site-packages/django/core/handlers/exception.py", line 55, in inner
    response = get_response(request)
  File "/home/an/python_examin/lib/python3.9/site-packages/django/core/handlers/base.py", line 197, in _get_response
    response = wrapped_callback(request, *callback_args, **callback_kwargs)
  File "./StudentExamination/views.py", line 293, in get_Logistic
    data = data["data"]["track_info"]["tracking"]["providers"][0]["events"]
KeyError: 'track_info'
[2024-01-04 00:46:27,605] [log.py:241] [log:log_response] [ERROR]- Internal Server Error: /api/getxx/
Traceback (most recent call last):
  File "/home/an/python_examin/lib/python3.9/site-packages/django/core/handlers/exception.py", line 55, in inner
    response = get_response(request)
  File "/home/an/python_examin/lib/python3.9/site-packages/django/core/handlers/base.py", line 197, in _get_response
    response = wrapped_callback(request, *callback_args, **callback_kwargs)
  File "./StudentExamination/views.py", line 293, in get_Logistic
    data = data["data"]["track_info"]["tracking"]["providers"][0]["events"]
KeyError: 'track_info'
[2024-01-04 01:06:27,691] [log.py:241] [log:log_response] [ERROR]- Internal Server Error: /api/getxx/
Traceback (most recent call last):
  File "/home/an/python_examin/lib/python3.9/site-packages/django/core/handlers/exception.py", line 55, in inner
    response = get_response(request)
  File "/home/an/python_examin/lib/python3.9/site-packages/django/core/handlers/base.py", line 197, in _get_response
    response = wrapped_callback(request, *callback_args, **callback_kwargs)
  File "./StudentExamination/views.py", line 293, in get_Logistic
    data = data["data"]["track_info"]["tracking"]["providers"][0]["events"]
KeyError: 'track_info'
[2024-01-04 01:36:27,783] [log.py:241] [log:log_response] [ERROR]- Internal Server Error: /api/getxx/
Traceback (most recent call last):
  File "/home/an/python_examin/lib/python3.9/site-packages/django/core/handlers/exception.py", line 55, in inner
    response = get_response(request)
  File "/home/an/python_examin/lib/python3.9/site-packages/django/core/handlers/base.py", line 197, in _get_response
    response = wrapped_callback(request, *callback_args, **callback_kwargs)
  File "./StudentExamination/views.py", line 293, in get_Logistic
    data = data["data"]["track_info"]["tracking"]["providers"][0]["events"]
KeyError: 'track_info'
