[2023-12-05 16:34:05,144] [log.py:241] [log:log_response] [ERROR]- Internal Server Error: /api/deletecommodity/
Traceback (most recent call last):
  File "D:\baiduwangpan\python_virtualenv\python_vx\lib\site-packages\django\core\handlers\exception.py", line 55, in inner
    response = get_response(request)
  File "D:\baiduwangpan\python_virtualenv\python_vx\lib\site-packages\django\core\handlers\base.py", line 204, in _get_response
    self.check_response(response, callback)
  File "D:\baiduwangpan\python_virtualenv\python_vx\lib\site-packages\django\core\handlers\base.py", line 332, in check_response
    raise ValueError(
ValueError: The view StudentExamination.views.deleteCommodity didn't return an HttpResponse object. It returned None instead.
[2023-12-05 16:34:05,159] [basehttp.py:187] [basehttp:log_message] [ERROR]- "POST /api/deletecommodity/ HTTP/1.1" 500 145
[2023-12-05 20:54:20,567] [log.py:241] [log:log_response] [ERROR]- Internal Server Error: /api/getxx/
Traceback (most recent call last):
  File "/home/an/python_examin/lib/python3.9/site-packages/django/core/handlers/exception.py", line 55, in inner
    response = get_response(request)
  File "/home/an/python_examin/lib/python3.9/site-packages/django/core/handlers/base.py", line 197, in _get_response
    response = wrapped_callback(request, *callback_args, **callback_kwargs)
  File "./StudentExamination/views.py", line 288, in get_Logistic
    data = data["data"]["track_info"]["tracking"]["providers"][0]["events"]
KeyError: 'track_info'
[2023-12-05 21:04:20,689] [log.py:241] [log:log_response] [ERROR]- Internal Server Error: /api/getxx/
Traceback (most recent call last):
  File "/home/an/python_examin/lib/python3.9/site-packages/django/core/handlers/exception.py", line 55, in inner
    response = get_response(request)
  File "/home/an/python_examin/lib/python3.9/site-packages/django/core/handlers/base.py", line 197, in _get_response
    response = wrapped_callback(request, *callback_args, **callback_kwargs)
  File "./StudentExamination/views.py", line 288, in get_Logistic
    data = data["data"]["track_info"]["tracking"]["providers"][0]["events"]
KeyError: 'track_info'
[2023-12-05 21:24:20,795] [log.py:241] [log:log_response] [ERROR]- Internal Server Error: /api/getxx/
Traceback (most recent call last):
  File "/home/an/python_examin/lib/python3.9/site-packages/django/core/handlers/exception.py", line 55, in inner
    response = get_response(request)
  File "/home/an/python_examin/lib/python3.9/site-packages/django/core/handlers/base.py", line 197, in _get_response
    response = wrapped_callback(request, *callback_args, **callback_kwargs)
  File "./StudentExamination/views.py", line 288, in get_Logistic
    data = data["data"]["track_info"]["tracking"]["providers"][0]["events"]
KeyError: 'track_info'
[2023-12-05 21:54:20,884] [log.py:241] [log:log_response] [ERROR]- Internal Server Error: /api/getxx/
Traceback (most recent call last):
  File "/home/an/python_examin/lib/python3.9/site-packages/django/core/handlers/exception.py", line 55, in inner
    response = get_response(request)
  File "/home/an/python_examin/lib/python3.9/site-packages/django/core/handlers/base.py", line 197, in _get_response
    response = wrapped_callback(request, *callback_args, **callback_kwargs)
  File "./StudentExamination/views.py", line 288, in get_Logistic
    data = data["data"]["track_info"]["tracking"]["providers"][0]["events"]
KeyError: 'track_info'
[2023-12-07 19:03:24,873] [log.py:241] [log:log_response] [ERROR]- Internal Server Error: /api/getxx/
Traceback (most recent call last):
  File "/home/an/python_examin/lib/python3.9/site-packages/django/core/handlers/exception.py", line 55, in inner
    response = get_response(request)
  File "/home/an/python_examin/lib/python3.9/site-packages/django/core/handlers/base.py", line 197, in _get_response
    response = wrapped_callback(request, *callback_args, **callback_kwargs)
  File "./StudentExamination/views.py", line 288, in get_Logistic
    data = data["data"]["track_info"]["tracking"]["providers"][0]["events"]
KeyError: 'track_info'
[2023-12-07 19:13:24,969] [log.py:241] [log:log_response] [ERROR]- Internal Server Error: /api/getxx/
Traceback (most recent call last):
  File "/home/an/python_examin/lib/python3.9/site-packages/django/core/handlers/exception.py", line 55, in inner
    response = get_response(request)
  File "/home/an/python_examin/lib/python3.9/site-packages/django/core/handlers/base.py", line 197, in _get_response
    response = wrapped_callback(request, *callback_args, **callback_kwargs)
  File "./StudentExamination/views.py", line 288, in get_Logistic
    data = data["data"]["track_info"]["tracking"]["providers"][0]["events"]
KeyError: 'track_info'
[2023-12-07 19:33:25,067] [log.py:241] [log:log_response] [ERROR]- Internal Server Error: /api/getxx/
Traceback (most recent call last):
  File "/home/an/python_examin/lib/python3.9/site-packages/django/core/handlers/exception.py", line 55, in inner
    response = get_response(request)
  File "/home/an/python_examin/lib/python3.9/site-packages/django/core/handlers/base.py", line 197, in _get_response
    response = wrapped_callback(request, *callback_args, **callback_kwargs)
  File "./StudentExamination/views.py", line 288, in get_Logistic
    data = data["data"]["track_info"]["tracking"]["providers"][0]["events"]
KeyError: 'track_info'
[2023-12-07 20:03:25,170] [log.py:241] [log:log_response] [ERROR]- Internal Server Error: /api/getxx/
Traceback (most recent call last):
  File "/home/an/python_examin/lib/python3.9/site-packages/django/core/handlers/exception.py", line 55, in inner
    response = get_response(request)
  File "/home/an/python_examin/lib/python3.9/site-packages/django/core/handlers/base.py", line 197, in _get_response
    response = wrapped_callback(request, *callback_args, **callback_kwargs)
  File "./StudentExamination/views.py", line 288, in get_Logistic
    data = data["data"]["track_info"]["tracking"]["providers"][0]["events"]
KeyError: 'track_info'
[2023-12-08 04:13:42,638] [log.py:241] [log:log_response] [ERROR]- Internal Server Error: /api/getxx/
Traceback (most recent call last):
  File "/home/an/python_examin/lib/python3.9/site-packages/django/core/handlers/exception.py", line 55, in inner
    response = get_response(request)
  File "/home/an/python_examin/lib/python3.9/site-packages/django/core/handlers/base.py", line 197, in _get_response
    response = wrapped_callback(request, *callback_args, **callback_kwargs)
  File "./StudentExamination/views.py", line 288, in get_Logistic
    data = data["data"]["track_info"]["tracking"]["providers"][0]["events"]
KeyError: 'track_info'
[2023-12-08 04:23:42,738] [log.py:241] [log:log_response] [ERROR]- Internal Server Error: /api/getxx/
Traceback (most recent call last):
  File "/home/an/python_examin/lib/python3.9/site-packages/django/core/handlers/exception.py", line 55, in inner
    response = get_response(request)
  File "/home/an/python_examin/lib/python3.9/site-packages/django/core/handlers/base.py", line 197, in _get_response
    response = wrapped_callback(request, *callback_args, **callback_kwargs)
  File "./StudentExamination/views.py", line 288, in get_Logistic
    data = data["data"]["track_info"]["tracking"]["providers"][0]["events"]
KeyError: 'track_info'
[2023-12-08 04:43:42,829] [log.py:241] [log:log_response] [ERROR]- Internal Server Error: /api/getxx/
Traceback (most recent call last):
  File "/home/an/python_examin/lib/python3.9/site-packages/django/core/handlers/exception.py", line 55, in inner
    response = get_response(request)
  File "/home/an/python_examin/lib/python3.9/site-packages/django/core/handlers/base.py", line 197, in _get_response
    response = wrapped_callback(request, *callback_args, **callback_kwargs)
  File "./StudentExamination/views.py", line 288, in get_Logistic
    data = data["data"]["track_info"]["tracking"]["providers"][0]["events"]
KeyError: 'track_info'
[2023-12-08 05:13:42,921] [log.py:241] [log:log_response] [ERROR]- Internal Server Error: /api/getxx/
Traceback (most recent call last):
  File "/home/an/python_examin/lib/python3.9/site-packages/django/core/handlers/exception.py", line 55, in inner
    response = get_response(request)
  File "/home/an/python_examin/lib/python3.9/site-packages/django/core/handlers/base.py", line 197, in _get_response
    response = wrapped_callback(request, *callback_args, **callback_kwargs)
  File "./StudentExamination/views.py", line 288, in get_Logistic
    data = data["data"]["track_info"]["tracking"]["providers"][0]["events"]
KeyError: 'track_info'
[2023-12-08 11:00:31,962] [exception.py:124] [exception:response_for_exception] [ERROR]- Invalid HTTP_HOST header: 'srv57c0d2365c3c.korsan.me:443srv57c0d2365c3c.korsan.me:443'. The domain name provided is not valid according to RFC 1034/1035.
Traceback (most recent call last):
  File "/home/an/python_examin/lib/python3.9/site-packages/django/core/handlers/exception.py", line 55, in inner
    response = get_response(request)
  File "/home/an/python_examin/lib/python3.9/site-packages/django/utils/deprecation.py", line 135, in __call__
    response = self.process_request(request)
  File "/home/an/python_examin/lib/python3.9/site-packages/django/middleware/common.py", line 48, in process_request
    host = request.get_host()
  File "/home/an/python_examin/lib/python3.9/site-packages/django/http/request.py", line 148, in get_host
    raise DisallowedHost(msg)
django.core.exceptions.DisallowedHost: Invalid HTTP_HOST header: 'srv57c0d2365c3c.korsan.me:443srv57c0d2365c3c.korsan.me:443'. The domain name provided is not valid according to RFC 1034/1035.
[2023-12-08 11:19:14,861] [exception.py:124] [exception:response_for_exception] [ERROR]- Invalid HTTP_HOST header: 'srv57c0d2365c3c.korsan.me:443srv57c0d2365c3c.korsan.me:443'. The domain name provided is not valid according to RFC 1034/1035.
Traceback (most recent call last):
  File "/home/an/python_examin/lib/python3.9/site-packages/django/core/handlers/exception.py", line 55, in inner
    response = get_response(request)
  File "/home/an/python_examin/lib/python3.9/site-packages/django/utils/deprecation.py", line 135, in __call__
    response = self.process_request(request)
  File "/home/an/python_examin/lib/python3.9/site-packages/django/middleware/common.py", line 48, in process_request
    host = request.get_host()
  File "/home/an/python_examin/lib/python3.9/site-packages/django/http/request.py", line 148, in get_host
    raise DisallowedHost(msg)
django.core.exceptions.DisallowedHost: Invalid HTTP_HOST header: 'srv57c0d2365c3c.korsan.me:443srv57c0d2365c3c.korsan.me:443'. The domain name provided is not valid according to RFC 1034/1035.
[2023-12-10 07:02:08,092] [log.py:241] [log:log_response] [ERROR]- Internal Server Error: /api/getxx/
Traceback (most recent call last):
  File "/home/an/python_examin/lib/python3.9/site-packages/django/core/handlers/exception.py", line 55, in inner
    response = get_response(request)
  File "/home/an/python_examin/lib/python3.9/site-packages/django/core/handlers/base.py", line 197, in _get_response
    response = wrapped_callback(request, *callback_args, **callback_kwargs)
  File "./StudentExamination/views.py", line 288, in get_Logistic
    data = data["data"]["track_info"]["tracking"]["providers"][0]["events"]
KeyError: 'track_info'
[2023-12-10 07:12:08,194] [log.py:241] [log:log_response] [ERROR]- Internal Server Error: /api/getxx/
Traceback (most recent call last):
  File "/home/an/python_examin/lib/python3.9/site-packages/django/core/handlers/exception.py", line 55, in inner
    response = get_response(request)
  File "/home/an/python_examin/lib/python3.9/site-packages/django/core/handlers/base.py", line 197, in _get_response
    response = wrapped_callback(request, *callback_args, **callback_kwargs)
  File "./StudentExamination/views.py", line 288, in get_Logistic
    data = data["data"]["track_info"]["tracking"]["providers"][0]["events"]
KeyError: 'track_info'
[2023-12-10 07:32:08,288] [log.py:241] [log:log_response] [ERROR]- Internal Server Error: /api/getxx/
Traceback (most recent call last):
  File "/home/an/python_examin/lib/python3.9/site-packages/django/core/handlers/exception.py", line 55, in inner
    response = get_response(request)
  File "/home/an/python_examin/lib/python3.9/site-packages/django/core/handlers/base.py", line 197, in _get_response
    response = wrapped_callback(request, *callback_args, **callback_kwargs)
  File "./StudentExamination/views.py", line 288, in get_Logistic
    data = data["data"]["track_info"]["tracking"]["providers"][0]["events"]
KeyError: 'track_info'
[2023-12-10 08:02:08,383] [log.py:241] [log:log_response] [ERROR]- Internal Server Error: /api/getxx/
Traceback (most recent call last):
  File "/home/an/python_examin/lib/python3.9/site-packages/django/core/handlers/exception.py", line 55, in inner
    response = get_response(request)
  File "/home/an/python_examin/lib/python3.9/site-packages/django/core/handlers/base.py", line 197, in _get_response
    response = wrapped_callback(request, *callback_args, **callback_kwargs)
  File "./StudentExamination/views.py", line 288, in get_Logistic
    data = data["data"]["track_info"]["tracking"]["providers"][0]["events"]
KeyError: 'track_info'
