[2023-11-20 07:15:51,377] [log.py:241] [log:log_response] [ERROR]- Internal Server Error: /api/getxx/
Traceback (most recent call last):
  File "/home/an/python_examin/lib/python3.9/site-packages/django/core/handlers/exception.py", line 55, in inner
    response = get_response(request)
  File "/home/an/python_examin/lib/python3.9/site-packages/django/core/handlers/base.py", line 197, in _get_response
    response = wrapped_callback(request, *callback_args, **callback_kwargs)
  File "./StudentExamination/views.py", line 238, in get_Logistic
    json.dump(obj=request.body,fp=f,ensure_ascii=False)
  File "/usr/local/lib/python3.9/json/__init__.py", line 179, in dump
    for chunk in iterable:
  File "/usr/local/lib/python3.9/json/encoder.py", line 438, in _iterencode
    o = _default(o)
  File "/usr/local/lib/python3.9/json/encoder.py", line 179, in default
    raise TypeError(f'Object of type {o.__class__.__name__} '
TypeError: Object of type bytes is not JSON serializable
[2023-11-20 07:22:39,861] [log.py:241] [log:log_response] [ERROR]- Internal Server Error: /api/getxx/
Traceback (most recent call last):
  File "/home/an/python_examin/lib/python3.9/site-packages/django/core/handlers/exception.py", line 55, in inner
    response = get_response(request)
  File "/home/an/python_examin/lib/python3.9/site-packages/django/core/handlers/base.py", line 197, in _get_response
    response = wrapped_callback(request, *callback_args, **callback_kwargs)
  File "./StudentExamination/views.py", line 239, in get_Logistic
    json.dump(obj=request.body,fp=f,ensure_ascii=False)
  File "/usr/local/lib/python3.9/json/__init__.py", line 179, in dump
    for chunk in iterable:
  File "/usr/local/lib/python3.9/json/encoder.py", line 438, in _iterencode
    o = _default(o)
  File "/usr/local/lib/python3.9/json/encoder.py", line 179, in default
    raise TypeError(f'Object of type {o.__class__.__name__} '
TypeError: Object of type bytes is not JSON serializable
[2023-11-20 07:25:51,618] [log.py:241] [log:log_response] [ERROR]- Internal Server Error: /api/getxx/
Traceback (most recent call last):
  File "/home/an/python_examin/lib/python3.9/site-packages/django/core/handlers/exception.py", line 55, in inner
    response = get_response(request)
  File "/home/an/python_examin/lib/python3.9/site-packages/django/core/handlers/base.py", line 197, in _get_response
    response = wrapped_callback(request, *callback_args, **callback_kwargs)
  File "./StudentExamination/views.py", line 239, in get_Logistic
    json.dump(obj=request.body,fp=f,ensure_ascii=False)
  File "/usr/local/lib/python3.9/json/__init__.py", line 179, in dump
    for chunk in iterable:
  File "/usr/local/lib/python3.9/json/encoder.py", line 438, in _iterencode
    o = _default(o)
  File "/usr/local/lib/python3.9/json/encoder.py", line 179, in default
    raise TypeError(f'Object of type {o.__class__.__name__} '
TypeError: Object of type bytes is not JSON serializable
[2023-11-20 07:32:39,965] [log.py:241] [log:log_response] [ERROR]- Internal Server Error: /api/getxx/
Traceback (most recent call last):
  File "/home/an/python_examin/lib/python3.9/site-packages/django/core/handlers/exception.py", line 55, in inner
    response = get_response(request)
  File "/home/an/python_examin/lib/python3.9/site-packages/django/core/handlers/base.py", line 197, in _get_response
    response = wrapped_callback(request, *callback_args, **callback_kwargs)
  File "./StudentExamination/views.py", line 239, in get_Logistic
    json.dump(obj=request.body,fp=f,ensure_ascii=False)
  File "/usr/local/lib/python3.9/json/__init__.py", line 179, in dump
    for chunk in iterable:
  File "/usr/local/lib/python3.9/json/encoder.py", line 438, in _iterencode
    o = _default(o)
  File "/usr/local/lib/python3.9/json/encoder.py", line 179, in default
    raise TypeError(f'Object of type {o.__class__.__name__} '
TypeError: Object of type bytes is not JSON serializable
[2023-11-20 07:45:51,760] [log.py:241] [log:log_response] [ERROR]- Internal Server Error: /api/getxx/
Traceback (most recent call last):
  File "/home/an/python_examin/lib/python3.9/site-packages/django/core/handlers/exception.py", line 55, in inner
    response = get_response(request)
  File "/home/an/python_examin/lib/python3.9/site-packages/django/core/handlers/base.py", line 197, in _get_response
    response = wrapped_callback(request, *callback_args, **callback_kwargs)
  File "./StudentExamination/views.py", line 239, in get_Logistic
    json.dump(obj=request.body,fp=f,ensure_ascii=False)
  File "/usr/local/lib/python3.9/json/__init__.py", line 179, in dump
    for chunk in iterable:
  File "/usr/local/lib/python3.9/json/encoder.py", line 438, in _iterencode
    o = _default(o)
  File "/usr/local/lib/python3.9/json/encoder.py", line 179, in default
    raise TypeError(f'Object of type {o.__class__.__name__} '
TypeError: Object of type bytes is not JSON serializable
[2023-11-20 07:52:40,152] [log.py:241] [log:log_response] [ERROR]- Internal Server Error: /api/getxx/
Traceback (most recent call last):
  File "/home/an/python_examin/lib/python3.9/site-packages/django/core/handlers/exception.py", line 55, in inner
    response = get_response(request)
  File "/home/an/python_examin/lib/python3.9/site-packages/django/core/handlers/base.py", line 197, in _get_response
    response = wrapped_callback(request, *callback_args, **callback_kwargs)
  File "./StudentExamination/views.py", line 239, in get_Logistic
    json.dump(obj=request.body,fp=f,ensure_ascii=False)
  File "/usr/local/lib/python3.9/json/__init__.py", line 179, in dump
    for chunk in iterable:
  File "/usr/local/lib/python3.9/json/encoder.py", line 438, in _iterencode
    o = _default(o)
  File "/usr/local/lib/python3.9/json/encoder.py", line 179, in default
    raise TypeError(f'Object of type {o.__class__.__name__} '
TypeError: Object of type bytes is not JSON serializable
