<<<<<<< Updated upstream
[2023-12-13 13:51:14,013] [log.py:241] [log:log_response] [WARNING]- Not Found: /static/plugins/bootstrap-3.4.1/css/bootstrap.min.css
[2023-12-13 13:51:14,014] [basehttp.py:187] [basehttp:log_message] [WARNING]- "GET /static/plugins/bootstrap-3.4.1/css/bootstrap.min.css HTTP/1.1" 404 13967
[2023-12-13 13:51:14,100] [log.py:241] [log:log_response] [WARNING]- Not Found: /favicon.ico
[2023-12-13 13:51:14,101] [basehttp.py:187] [basehttp:log_message] [WARNING]- "GET /favicon.ico HTTP/1.1" 404 13967
=======
[2023-12-13 04:48:19,476] [log.py:241] [log:log_response] [WARNING]- Not Found: /api/v1/dashboard/base/all/all
[2023-12-13 05:33:55,130] [log.py:241] [log:log_response] [WARNING]- Not Found: /api/v1/dashboard/base/all/all
>>>>>>> Stashed changes
[2023-12-14 01:59:21,626] [log.py:241] [log:log_response] [WARNING]- Not Found: /favicon.ico
[2023-12-14 11:50:49,163] [log.py:241] [log:log_response] [ERROR]- Internal Server Error: /api/updata/
Traceback (most recent call last):
  File "/home/an/python_examin/lib/python3.9/site-packages/django/core/handlers/exception.py", line 55, in inner
    response = get_response(request)
  File "/home/an/python_examin/lib/python3.9/site-packages/django/core/handlers/base.py", line 197, in _get_response
    response = wrapped_callback(request, *callback_args, **callback_kwargs)
  File "/usr/local/lib/python3.9/contextlib.py", line 79, in inner
    return func(*args, **kwds)
  File "./StudentExamination/views.py", line 335, in updata_information
    plat = json.loads(by)
  File "/usr/local/lib/python3.9/json/__init__.py", line 346, in loads
    return _default_decoder.decode(s)
  File "/usr/local/lib/python3.9/json/decoder.py", line 337, in decode
    obj, end = self.raw_decode(s, idx=_w(s, 0).end())
  File "/usr/local/lib/python3.9/json/decoder.py", line 355, in raw_decode
    raise JSONDecodeError("Expecting value", s, err.value) from None
json.decoder.JSONDecodeError: Expecting value: line 1 column 1 (char 0)
[2023-12-14 11:52:49,961] [log.py:241] [log:log_response] [ERROR]- Internal Server Error: /api/updata/
Traceback (most recent call last):
  File "/home/an/python_examin/lib/python3.9/site-packages/django/core/handlers/exception.py", line 55, in inner
    response = get_response(request)
  File "/home/an/python_examin/lib/python3.9/site-packages/django/core/handlers/base.py", line 197, in _get_response
    response = wrapped_callback(request, *callback_args, **callback_kwargs)
  File "/usr/local/lib/python3.9/contextlib.py", line 79, in inner
    return func(*args, **kwds)
  File "./StudentExamination/views.py", line 335, in updata_information
    plat = json.loads(by)
  File "/usr/local/lib/python3.9/json/__init__.py", line 346, in loads
    return _default_decoder.decode(s)
  File "/usr/local/lib/python3.9/json/decoder.py", line 337, in decode
    obj, end = self.raw_decode(s, idx=_w(s, 0).end())
  File "/usr/local/lib/python3.9/json/decoder.py", line 355, in raw_decode
    raise JSONDecodeError("Expecting value", s, err.value) from None
json.decoder.JSONDecodeError: Expecting value: line 1 column 1 (char 0)
[2023-12-14 11:54:48,617] [log.py:241] [log:log_response] [ERROR]- Internal Server Error: /api/updata/
Traceback (most recent call last):
  File "/home/an/python_examin/lib/python3.9/site-packages/django/core/handlers/exception.py", line 55, in inner
    response = get_response(request)
  File "/home/an/python_examin/lib/python3.9/site-packages/django/core/handlers/base.py", line 197, in _get_response
    response = wrapped_callback(request, *callback_args, **callback_kwargs)
  File "/usr/local/lib/python3.9/contextlib.py", line 79, in inner
    return func(*args, **kwds)
  File "./StudentExamination/views.py", line 335, in updata_information
    plat = json.loads(by)
  File "/usr/local/lib/python3.9/json/__init__.py", line 346, in loads
    return _default_decoder.decode(s)
  File "/usr/local/lib/python3.9/json/decoder.py", line 337, in decode
    obj, end = self.raw_decode(s, idx=_w(s, 0).end())
  File "/usr/local/lib/python3.9/json/decoder.py", line 355, in raw_decode
    raise JSONDecodeError("Expecting value", s, err.value) from None
json.decoder.JSONDecodeError: Expecting value: line 1 column 1 (char 0)
[2023-12-14 12:04:33,323] [log.py:241] [log:log_response] [ERROR]- Internal Server Error: /api/updata/
Traceback (most recent call last):
  File "/home/an/python_examin/lib/python3.9/site-packages/django/core/handlers/exception.py", line 55, in inner
    response = get_response(request)
  File "/home/an/python_examin/lib/python3.9/site-packages/django/core/handlers/base.py", line 197, in _get_response
    response = wrapped_callback(request, *callback_args, **callback_kwargs)
  File "/usr/local/lib/python3.9/contextlib.py", line 79, in inner
    return func(*args, **kwds)
  File "./StudentExamination/views.py", line 335, in updata_information
    plat = json.loads(by)
  File "/usr/local/lib/python3.9/json/__init__.py", line 346, in loads
    return _default_decoder.decode(s)
  File "/usr/local/lib/python3.9/json/decoder.py", line 337, in decode
    obj, end = self.raw_decode(s, idx=_w(s, 0).end())
  File "/usr/local/lib/python3.9/json/decoder.py", line 355, in raw_decode
    raise JSONDecodeError("Expecting value", s, err.value) from None
json.decoder.JSONDecodeError: Expecting value: line 1 column 1 (char 0)
[2023-12-14 12:04:49,007] [log.py:241] [log:log_response] [ERROR]- Internal Server Error: /api/updata/
Traceback (most recent call last):
  File "/home/an/python_examin/lib/python3.9/site-packages/django/core/handlers/exception.py", line 55, in inner
    response = get_response(request)
  File "/home/an/python_examin/lib/python3.9/site-packages/django/core/handlers/base.py", line 197, in _get_response
    response = wrapped_callback(request, *callback_args, **callback_kwargs)
  File "/usr/local/lib/python3.9/contextlib.py", line 79, in inner
    return func(*args, **kwds)
  File "./StudentExamination/views.py", line 335, in updata_information
    plat = json.loads(by)
  File "/usr/local/lib/python3.9/json/__init__.py", line 346, in loads
    return _default_decoder.decode(s)
  File "/usr/local/lib/python3.9/json/decoder.py", line 337, in decode
    obj, end = self.raw_decode(s, idx=_w(s, 0).end())
  File "/usr/local/lib/python3.9/json/decoder.py", line 355, in raw_decode
    raise JSONDecodeError("Expecting value", s, err.value) from None
json.decoder.JSONDecodeError: Expecting value: line 1 column 1 (char 0)
[2023-12-14 12:10:11,989] [log.py:241] [log:log_response] [ERROR]- Internal Server Error: /api/updata/
Traceback (most recent call last):
  File "/home/an/python_examin/lib/python3.9/site-packages/django/core/handlers/exception.py", line 55, in inner
    response = get_response(request)
  File "/home/an/python_examin/lib/python3.9/site-packages/django/core/handlers/base.py", line 197, in _get_response
    response = wrapped_callback(request, *callback_args, **callback_kwargs)
  File "/usr/local/lib/python3.9/contextlib.py", line 79, in inner
    return func(*args, **kwds)
  File "./StudentExamination/views.py", line 335, in updata_information
    plat = json.loads(by)
  File "/usr/local/lib/python3.9/json/__init__.py", line 346, in loads
    return _default_decoder.decode(s)
  File "/usr/local/lib/python3.9/json/decoder.py", line 337, in decode
    obj, end = self.raw_decode(s, idx=_w(s, 0).end())
  File "/usr/local/lib/python3.9/json/decoder.py", line 355, in raw_decode
    raise JSONDecodeError("Expecting value", s, err.value) from None
json.decoder.JSONDecodeError: Expecting value: line 1 column 1 (char 0)
[2023-12-14 12:12:24,714] [log.py:241] [log:log_response] [ERROR]- Internal Server Error: /api/updata/
Traceback (most recent call last):
  File "/home/an/python_examin/lib/python3.9/site-packages/django/core/handlers/exception.py", line 55, in inner
    response = get_response(request)
  File "/home/an/python_examin/lib/python3.9/site-packages/django/core/handlers/base.py", line 197, in _get_response
    response = wrapped_callback(request, *callback_args, **callback_kwargs)
  File "/usr/local/lib/python3.9/contextlib.py", line 79, in inner
    return func(*args, **kwds)
  File "./StudentExamination/views.py", line 335, in updata_information
    plat = json.loads(by)
  File "/usr/local/lib/python3.9/json/__init__.py", line 346, in loads
    return _default_decoder.decode(s)
  File "/usr/local/lib/python3.9/json/decoder.py", line 337, in decode
    obj, end = self.raw_decode(s, idx=_w(s, 0).end())
  File "/usr/local/lib/python3.9/json/decoder.py", line 355, in raw_decode
    raise JSONDecodeError("Expecting value", s, err.value) from None
json.decoder.JSONDecodeError: Expecting value: line 1 column 1 (char 0)
[2023-12-14 12:16:12,150] [log.py:241] [log:log_response] [ERROR]- Internal Server Error: /api/addmain/
Traceback (most recent call last):
  File "/home/an/python_examin/lib/python3.9/site-packages/django/core/handlers/exception.py", line 55, in inner
    response = get_response(request)
  File "/home/an/python_examin/lib/python3.9/site-packages/django/core/handlers/base.py", line 197, in _get_response
    response = wrapped_callback(request, *callback_args, **callback_kwargs)
  File "/usr/local/lib/python3.9/contextlib.py", line 79, in inner
    return func(*args, **kwds)
  File "./StudentExamination/views.py", line 223, in add_index
    plat = json.loads(by)
  File "/usr/local/lib/python3.9/json/__init__.py", line 346, in loads
    return _default_decoder.decode(s)
  File "/usr/local/lib/python3.9/json/decoder.py", line 337, in decode
    obj, end = self.raw_decode(s, idx=_w(s, 0).end())
  File "/usr/local/lib/python3.9/json/decoder.py", line 355, in raw_decode
    raise JSONDecodeError("Expecting value", s, err.value) from None
json.decoder.JSONDecodeError: Expecting value: line 1 column 1 (char 0)
[2023-12-14 12:20:58,621] [log.py:241] [log:log_response] [ERROR]- Internal Server Error: /api/updata/
Traceback (most recent call last):
  File "/home/an/python_examin/lib/python3.9/site-packages/django/core/handlers/exception.py", line 55, in inner
    response = get_response(request)
  File "/home/an/python_examin/lib/python3.9/site-packages/django/core/handlers/base.py", line 197, in _get_response
    response = wrapped_callback(request, *callback_args, **callback_kwargs)
  File "/usr/local/lib/python3.9/contextlib.py", line 79, in inner
    return func(*args, **kwds)
  File "./StudentExamination/views.py", line 335, in updata_information
    plat = json.loads(by)
  File "/usr/local/lib/python3.9/json/__init__.py", line 346, in loads
    return _default_decoder.decode(s)
  File "/usr/local/lib/python3.9/json/decoder.py", line 337, in decode
    obj, end = self.raw_decode(s, idx=_w(s, 0).end())
  File "/usr/local/lib/python3.9/json/decoder.py", line 355, in raw_decode
    raise JSONDecodeError("Expecting value", s, err.value) from None
json.decoder.JSONDecodeError: Expecting value: line 1 column 1 (char 0)
[2023-12-14 12:45:11,807] [log.py:241] [log:log_response] [ERROR]- Internal Server Error: /api/addmain/
Traceback (most recent call last):
  File "/home/an/python_examin/lib/python3.9/site-packages/django/core/handlers/exception.py", line 55, in inner
    response = get_response(request)
  File "/home/an/python_examin/lib/python3.9/site-packages/django/core/handlers/base.py", line 197, in _get_response
    response = wrapped_callback(request, *callback_args, **callback_kwargs)
  File "/usr/local/lib/python3.9/contextlib.py", line 79, in inner
    return func(*args, **kwds)
  File "./StudentExamination/views.py", line 223, in add_index
    plat = json.loads(by)
  File "/usr/local/lib/python3.9/json/__init__.py", line 346, in loads
    return _default_decoder.decode(s)
  File "/usr/local/lib/python3.9/json/decoder.py", line 337, in decode
    obj, end = self.raw_decode(s, idx=_w(s, 0).end())
  File "/usr/local/lib/python3.9/json/decoder.py", line 353, in raw_decode
    obj, end = self.scan_once(s, idx)
json.decoder.JSONDecodeError: Expecting property name enclosed in double quotes: line 1 column 2 (char 1)
[2023-12-14 12:45:18,979] [log.py:241] [log:log_response] [ERROR]- Internal Server Error: /api/addmain/
Traceback (most recent call last):
  File "/home/an/python_examin/lib/python3.9/site-packages/django/core/handlers/exception.py", line 55, in inner
    response = get_response(request)
  File "/home/an/python_examin/lib/python3.9/site-packages/django/core/handlers/base.py", line 197, in _get_response
    response = wrapped_callback(request, *callback_args, **callback_kwargs)
  File "/usr/local/lib/python3.9/contextlib.py", line 79, in inner
    return func(*args, **kwds)
  File "./StudentExamination/views.py", line 223, in add_index
    plat = json.loads(by)
  File "/usr/local/lib/python3.9/json/__init__.py", line 346, in loads
    return _default_decoder.decode(s)
  File "/usr/local/lib/python3.9/json/decoder.py", line 337, in decode
    obj, end = self.raw_decode(s, idx=_w(s, 0).end())
  File "/usr/local/lib/python3.9/json/decoder.py", line 353, in raw_decode
    obj, end = self.scan_once(s, idx)
json.decoder.JSONDecodeError: Expecting property name enclosed in double quotes: line 1 column 2 (char 1)
[2023-12-14 12:45:24,781] [log.py:241] [log:log_response] [ERROR]- Internal Server Error: /api/addmain/
Traceback (most recent call last):
  File "/home/an/python_examin/lib/python3.9/site-packages/django/core/handlers/exception.py", line 55, in inner
    response = get_response(request)
  File "/home/an/python_examin/lib/python3.9/site-packages/django/core/handlers/base.py", line 197, in _get_response
    response = wrapped_callback(request, *callback_args, **callback_kwargs)
  File "/usr/local/lib/python3.9/contextlib.py", line 79, in inner
    return func(*args, **kwds)
  File "./StudentExamination/views.py", line 223, in add_index
    plat = json.loads(by)
  File "/usr/local/lib/python3.9/json/__init__.py", line 346, in loads
    return _default_decoder.decode(s)
  File "/usr/local/lib/python3.9/json/decoder.py", line 337, in decode
    obj, end = self.raw_decode(s, idx=_w(s, 0).end())
  File "/usr/local/lib/python3.9/json/decoder.py", line 353, in raw_decode
    obj, end = self.scan_once(s, idx)
json.decoder.JSONDecodeError: Expecting property name enclosed in double quotes: line 1 column 2 (char 1)
[2023-12-14 12:47:42,659] [log.py:241] [log:log_response] [ERROR]- Internal Server Error: /api/addmain/
Traceback (most recent call last):
  File "/home/an/python_examin/lib/python3.9/site-packages/django/core/handlers/exception.py", line 55, in inner
    response = get_response(request)
  File "/home/an/python_examin/lib/python3.9/site-packages/django/core/handlers/base.py", line 197, in _get_response
    response = wrapped_callback(request, *callback_args, **callback_kwargs)
  File "/usr/local/lib/python3.9/contextlib.py", line 79, in inner
    return func(*args, **kwds)
  File "./StudentExamination/views.py", line 223, in add_index
    plat = json.loads(by)
  File "/usr/local/lib/python3.9/json/__init__.py", line 346, in loads
    return _default_decoder.decode(s)
  File "/usr/local/lib/python3.9/json/decoder.py", line 337, in decode
    obj, end = self.raw_decode(s, idx=_w(s, 0).end())
  File "/usr/local/lib/python3.9/json/decoder.py", line 353, in raw_decode
    obj, end = self.scan_once(s, idx)
json.decoder.JSONDecodeError: Expecting property name enclosed in double quotes: line 2 column 1 (char 3)
[2023-12-14 12:48:08,021] [log.py:241] [log:log_response] [ERROR]- Internal Server Error: /api/addmain/
Traceback (most recent call last):
  File "/home/an/python_examin/lib/python3.9/site-packages/django/core/handlers/exception.py", line 55, in inner
    response = get_response(request)
  File "/home/an/python_examin/lib/python3.9/site-packages/django/core/handlers/base.py", line 197, in _get_response
    response = wrapped_callback(request, *callback_args, **callback_kwargs)
  File "/usr/local/lib/python3.9/contextlib.py", line 79, in inner
    return func(*args, **kwds)
  File "./StudentExamination/views.py", line 223, in add_index
    plat = json.loads(by)
  File "/usr/local/lib/python3.9/json/__init__.py", line 346, in loads
    return _default_decoder.decode(s)
  File "/usr/local/lib/python3.9/json/decoder.py", line 337, in decode
    obj, end = self.raw_decode(s, idx=_w(s, 0).end())
  File "/usr/local/lib/python3.9/json/decoder.py", line 353, in raw_decode
    obj, end = self.scan_once(s, idx)
json.decoder.JSONDecodeError: Expecting property name enclosed in double quotes: line 2 column 1 (char 3)
[2023-12-14 12:49:01,084] [log.py:241] [log:log_response] [ERROR]- Internal Server Error: /api/addmain/
Traceback (most recent call last):
  File "/home/an/python_examin/lib/python3.9/site-packages/django/core/handlers/exception.py", line 55, in inner
    response = get_response(request)
  File "/home/an/python_examin/lib/python3.9/site-packages/django/core/handlers/base.py", line 197, in _get_response
    response = wrapped_callback(request, *callback_args, **callback_kwargs)
  File "/usr/local/lib/python3.9/contextlib.py", line 79, in inner
    return func(*args, **kwds)
  File "./StudentExamination/views.py", line 223, in add_index
    plat = json.loads(by)
  File "/usr/local/lib/python3.9/json/__init__.py", line 346, in loads
    return _default_decoder.decode(s)
  File "/usr/local/lib/python3.9/json/decoder.py", line 337, in decode
    obj, end = self.raw_decode(s, idx=_w(s, 0).end())
  File "/usr/local/lib/python3.9/json/decoder.py", line 353, in raw_decode
    obj, end = self.scan_once(s, idx)
json.decoder.JSONDecodeError: Expecting property name enclosed in double quotes: line 2 column 1 (char 3)
[2023-12-14 12:50:14,833] [log.py:241] [log:log_response] [ERROR]- Internal Server Error: /api/addmain/
Traceback (most recent call last):
  File "/home/an/python_examin/lib/python3.9/site-packages/django/core/handlers/exception.py", line 55, in inner
    response = get_response(request)
  File "/home/an/python_examin/lib/python3.9/site-packages/django/core/handlers/base.py", line 197, in _get_response
    response = wrapped_callback(request, *callback_args, **callback_kwargs)
  File "/usr/local/lib/python3.9/contextlib.py", line 79, in inner
    return func(*args, **kwds)
  File "./StudentExamination/views.py", line 223, in add_index
    plat = json.loads(by)
  File "/usr/local/lib/python3.9/json/__init__.py", line 346, in loads
    return _default_decoder.decode(s)
  File "/usr/local/lib/python3.9/json/decoder.py", line 337, in decode
    obj, end = self.raw_decode(s, idx=_w(s, 0).end())
  File "/usr/local/lib/python3.9/json/decoder.py", line 353, in raw_decode
    obj, end = self.scan_once(s, idx)
json.decoder.JSONDecodeError: Expecting property name enclosed in double quotes: line 2 column 1 (char 3)
[2023-12-14 12:50:16,787] [log.py:241] [log:log_response] [ERROR]- Internal Server Error: /api/addmain/
Traceback (most recent call last):
  File "/home/an/python_examin/lib/python3.9/site-packages/django/core/handlers/exception.py", line 55, in inner
    response = get_response(request)
  File "/home/an/python_examin/lib/python3.9/site-packages/django/core/handlers/base.py", line 197, in _get_response
    response = wrapped_callback(request, *callback_args, **callback_kwargs)
  File "/usr/local/lib/python3.9/contextlib.py", line 79, in inner
    return func(*args, **kwds)
  File "./StudentExamination/views.py", line 223, in add_index
    plat = json.loads(by)
  File "/usr/local/lib/python3.9/json/__init__.py", line 346, in loads
    return _default_decoder.decode(s)
  File "/usr/local/lib/python3.9/json/decoder.py", line 337, in decode
    obj, end = self.raw_decode(s, idx=_w(s, 0).end())
  File "/usr/local/lib/python3.9/json/decoder.py", line 353, in raw_decode
    obj, end = self.scan_once(s, idx)
json.decoder.JSONDecodeError: Expecting property name enclosed in double quotes: line 2 column 1 (char 3)
[2023-12-14 12:50:57,959] [log.py:241] [log:log_response] [ERROR]- Internal Server Error: /api/addmain/
Traceback (most recent call last):
  File "/home/an/python_examin/lib/python3.9/site-packages/django/core/handlers/exception.py", line 55, in inner
    response = get_response(request)
  File "/home/an/python_examin/lib/python3.9/site-packages/django/core/handlers/base.py", line 197, in _get_response
    response = wrapped_callback(request, *callback_args, **callback_kwargs)
  File "/usr/local/lib/python3.9/contextlib.py", line 79, in inner
    return func(*args, **kwds)
  File "./StudentExamination/views.py", line 223, in add_index
    plat = json.loads(by)
  File "/usr/local/lib/python3.9/json/__init__.py", line 346, in loads
    return _default_decoder.decode(s)
  File "/usr/local/lib/python3.9/json/decoder.py", line 337, in decode
    obj, end = self.raw_decode(s, idx=_w(s, 0).end())
  File "/usr/local/lib/python3.9/json/decoder.py", line 353, in raw_decode
    obj, end = self.scan_once(s, idx)
json.decoder.JSONDecodeError: Expecting property name enclosed in double quotes: line 2 column 1 (char 3)
[2023-12-14 12:51:05,033] [log.py:241] [log:log_response] [ERROR]- Internal Server Error: /api/addmain/
Traceback (most recent call last):
  File "/home/an/python_examin/lib/python3.9/site-packages/django/core/handlers/exception.py", line 55, in inner
    response = get_response(request)
  File "/home/an/python_examin/lib/python3.9/site-packages/django/core/handlers/base.py", line 197, in _get_response
    response = wrapped_callback(request, *callback_args, **callback_kwargs)
  File "/usr/local/lib/python3.9/contextlib.py", line 79, in inner
    return func(*args, **kwds)
  File "./StudentExamination/views.py", line 223, in add_index
    plat = json.loads(by)
  File "/usr/local/lib/python3.9/json/__init__.py", line 346, in loads
    return _default_decoder.decode(s)
  File "/usr/local/lib/python3.9/json/decoder.py", line 337, in decode
    obj, end = self.raw_decode(s, idx=_w(s, 0).end())
  File "/usr/local/lib/python3.9/json/decoder.py", line 353, in raw_decode
    obj, end = self.scan_once(s, idx)
json.decoder.JSONDecodeError: Expecting property name enclosed in double quotes: line 2 column 1 (char 3)
[2023-12-14 12:51:14,054] [log.py:241] [log:log_response] [ERROR]- Internal Server Error: /api/addmain/
Traceback (most recent call last):
  File "/home/an/python_examin/lib/python3.9/site-packages/django/core/handlers/exception.py", line 55, in inner
    response = get_response(request)
  File "/home/an/python_examin/lib/python3.9/site-packages/django/core/handlers/base.py", line 197, in _get_response
    response = wrapped_callback(request, *callback_args, **callback_kwargs)
  File "/usr/local/lib/python3.9/contextlib.py", line 79, in inner
    return func(*args, **kwds)
  File "./StudentExamination/views.py", line 223, in add_index
    plat = json.loads(by)
  File "/usr/local/lib/python3.9/json/__init__.py", line 346, in loads
    return _default_decoder.decode(s)
  File "/usr/local/lib/python3.9/json/decoder.py", line 337, in decode
    obj, end = self.raw_decode(s, idx=_w(s, 0).end())
  File "/usr/local/lib/python3.9/json/decoder.py", line 353, in raw_decode
    obj, end = self.scan_once(s, idx)
json.decoder.JSONDecodeError: Expecting property name enclosed in double quotes: line 2 column 1 (char 3)
[2023-12-14 12:51:53,879] [log.py:241] [log:log_response] [ERROR]- Internal Server Error: /api/addmain/
Traceback (most recent call last):
  File "/home/an/python_examin/lib/python3.9/site-packages/django/core/handlers/exception.py", line 55, in inner
    response = get_response(request)
  File "/home/an/python_examin/lib/python3.9/site-packages/django/core/handlers/base.py", line 197, in _get_response
    response = wrapped_callback(request, *callback_args, **callback_kwargs)
  File "/usr/local/lib/python3.9/contextlib.py", line 79, in inner
    return func(*args, **kwds)
  File "./StudentExamination/views.py", line 223, in add_index
    plat = json.loads(by)
  File "/usr/local/lib/python3.9/json/__init__.py", line 346, in loads
    return _default_decoder.decode(s)
  File "/usr/local/lib/python3.9/json/decoder.py", line 337, in decode
    obj, end = self.raw_decode(s, idx=_w(s, 0).end())
  File "/usr/local/lib/python3.9/json/decoder.py", line 353, in raw_decode
    obj, end = self.scan_once(s, idx)
json.decoder.JSONDecodeError: Expecting property name enclosed in double quotes: line 2 column 1 (char 3)
[2023-12-14 12:51:58,029] [log.py:241] [log:log_response] [ERROR]- Internal Server Error: /api/addmain/
Traceback (most recent call last):
  File "/home/an/python_examin/lib/python3.9/site-packages/django/core/handlers/exception.py", line 55, in inner
    response = get_response(request)
  File "/home/an/python_examin/lib/python3.9/site-packages/django/core/handlers/base.py", line 197, in _get_response
    response = wrapped_callback(request, *callback_args, **callback_kwargs)
  File "/usr/local/lib/python3.9/contextlib.py", line 79, in inner
    return func(*args, **kwds)
  File "./StudentExamination/views.py", line 223, in add_index
    plat = json.loads(by)
  File "/usr/local/lib/python3.9/json/__init__.py", line 346, in loads
    return _default_decoder.decode(s)
  File "/usr/local/lib/python3.9/json/decoder.py", line 337, in decode
    obj, end = self.raw_decode(s, idx=_w(s, 0).end())
  File "/usr/local/lib/python3.9/json/decoder.py", line 353, in raw_decode
    obj, end = self.scan_once(s, idx)
json.decoder.JSONDecodeError: Expecting property name enclosed in double quotes: line 2 column 1 (char 3)
[2023-12-14 12:53:55,576] [log.py:241] [log:log_response] [ERROR]- Internal Server Error: /api/addmain/
Traceback (most recent call last):
  File "/home/an/python_examin/lib/python3.9/site-packages/django/core/handlers/exception.py", line 55, in inner
    response = get_response(request)
  File "/home/an/python_examin/lib/python3.9/site-packages/django/core/handlers/base.py", line 197, in _get_response
    response = wrapped_callback(request, *callback_args, **callback_kwargs)
  File "/usr/local/lib/python3.9/contextlib.py", line 79, in inner
    return func(*args, **kwds)
  File "./StudentExamination/views.py", line 223, in add_index
    plat = json.loads(by)
  File "/usr/local/lib/python3.9/json/__init__.py", line 346, in loads
    return _default_decoder.decode(s)
  File "/usr/local/lib/python3.9/json/decoder.py", line 337, in decode
    obj, end = self.raw_decode(s, idx=_w(s, 0).end())
  File "/usr/local/lib/python3.9/json/decoder.py", line 353, in raw_decode
    obj, end = self.scan_once(s, idx)
json.decoder.JSONDecodeError: Expecting property name enclosed in double quotes: line 2 column 1 (char 3)
[2023-12-14 12:55:42,943] [log.py:241] [log:log_response] [ERROR]- Internal Server Error: /api/addmain/
Traceback (most recent call last):
  File "/home/an/python_examin/lib/python3.9/site-packages/django/core/handlers/exception.py", line 55, in inner
    response = get_response(request)
  File "/home/an/python_examin/lib/python3.9/site-packages/django/core/handlers/base.py", line 197, in _get_response
    response = wrapped_callback(request, *callback_args, **callback_kwargs)
  File "/usr/local/lib/python3.9/contextlib.py", line 79, in inner
    return func(*args, **kwds)
  File "./StudentExamination/views.py", line 223, in add_index
    plat = json.loads(by)
  File "/usr/local/lib/python3.9/json/__init__.py", line 346, in loads
    return _default_decoder.decode(s)
  File "/usr/local/lib/python3.9/json/decoder.py", line 337, in decode
    obj, end = self.raw_decode(s, idx=_w(s, 0).end())
  File "/usr/local/lib/python3.9/json/decoder.py", line 353, in raw_decode
    obj, end = self.scan_once(s, idx)
json.decoder.JSONDecodeError: Expecting property name enclosed in double quotes: line 2 column 1 (char 3)
[2023-12-14 12:56:42,453] [log.py:241] [log:log_response] [ERROR]- Internal Server Error: /api/addmain/
Traceback (most recent call last):
  File "/home/an/python_examin/lib/python3.9/site-packages/django/core/handlers/exception.py", line 55, in inner
    response = get_response(request)
  File "/home/an/python_examin/lib/python3.9/site-packages/django/core/handlers/base.py", line 197, in _get_response
    response = wrapped_callback(request, *callback_args, **callback_kwargs)
  File "/usr/local/lib/python3.9/contextlib.py", line 79, in inner
    return func(*args, **kwds)
  File "./StudentExamination/views.py", line 223, in add_index
    plat = json.loads(by)
  File "/usr/local/lib/python3.9/json/__init__.py", line 346, in loads
    return _default_decoder.decode(s)
  File "/usr/local/lib/python3.9/json/decoder.py", line 337, in decode
    obj, end = self.raw_decode(s, idx=_w(s, 0).end())
  File "/usr/local/lib/python3.9/json/decoder.py", line 353, in raw_decode
    obj, end = self.scan_once(s, idx)
json.decoder.JSONDecodeError: Expecting property name enclosed in double quotes: line 2 column 1 (char 11)
[2023-12-14 12:57:01,441] [log.py:241] [log:log_response] [ERROR]- Internal Server Error: /api/addmain/
Traceback (most recent call last):
  File "/home/an/python_examin/lib/python3.9/site-packages/django/core/handlers/exception.py", line 55, in inner
    response = get_response(request)
  File "/home/an/python_examin/lib/python3.9/site-packages/django/core/handlers/base.py", line 197, in _get_response
    response = wrapped_callback(request, *callback_args, **callback_kwargs)
  File "/usr/local/lib/python3.9/contextlib.py", line 79, in inner
    return func(*args, **kwds)
  File "./StudentExamination/views.py", line 223, in add_index
    plat = json.loads(by)
  File "/usr/local/lib/python3.9/json/__init__.py", line 346, in loads
    return _default_decoder.decode(s)
  File "/usr/local/lib/python3.9/json/decoder.py", line 337, in decode
    obj, end = self.raw_decode(s, idx=_w(s, 0).end())
  File "/usr/local/lib/python3.9/json/decoder.py", line 353, in raw_decode
    obj, end = self.scan_once(s, idx)
json.decoder.JSONDecodeError: Expecting property name enclosed in double quotes: line 3 column 1 (char 17)
[2023-12-14 12:57:09,499] [log.py:241] [log:log_response] [ERROR]- Internal Server Error: /api/addmain/
Traceback (most recent call last):
  File "/home/an/python_examin/lib/python3.9/site-packages/django/core/handlers/exception.py", line 55, in inner
    response = get_response(request)
  File "/home/an/python_examin/lib/python3.9/site-packages/django/core/handlers/base.py", line 197, in _get_response
    response = wrapped_callback(request, *callback_args, **callback_kwargs)
  File "/usr/local/lib/python3.9/contextlib.py", line 79, in inner
    return func(*args, **kwds)
  File "./StudentExamination/views.py", line 223, in add_index
    plat = json.loads(by)
  File "/usr/local/lib/python3.9/json/__init__.py", line 346, in loads
    return _default_decoder.decode(s)
  File "/usr/local/lib/python3.9/json/decoder.py", line 337, in decode
    obj, end = self.raw_decode(s, idx=_w(s, 0).end())
  File "/usr/local/lib/python3.9/json/decoder.py", line 353, in raw_decode
    obj, end = self.scan_once(s, idx)
json.decoder.JSONDecodeError: Expecting property name enclosed in double quotes: line 3 column 1 (char 17)
[2023-12-14 12:57:14,207] [log.py:241] [log:log_response] [ERROR]- Internal Server Error: /api/addmain/
Traceback (most recent call last):
  File "/home/an/python_examin/lib/python3.9/site-packages/django/core/handlers/exception.py", line 55, in inner
    response = get_response(request)
  File "/home/an/python_examin/lib/python3.9/site-packages/django/core/handlers/base.py", line 197, in _get_response
    response = wrapped_callback(request, *callback_args, **callback_kwargs)
  File "/usr/local/lib/python3.9/contextlib.py", line 79, in inner
    return func(*args, **kwds)
  File "./StudentExamination/views.py", line 223, in add_index
    plat = json.loads(by)
  File "/usr/local/lib/python3.9/json/__init__.py", line 346, in loads
    return _default_decoder.decode(s)
  File "/usr/local/lib/python3.9/json/decoder.py", line 337, in decode
    obj, end = self.raw_decode(s, idx=_w(s, 0).end())
  File "/usr/local/lib/python3.9/json/decoder.py", line 353, in raw_decode
    obj, end = self.scan_once(s, idx)
json.decoder.JSONDecodeError: Expecting property name enclosed in double quotes: line 3 column 1 (char 17)
[2023-12-14 13:30:19,405] [log.py:241] [log:log_response] [ERROR]- Internal Server Error: /api/addmain/
Traceback (most recent call last):
  File "/home/an/python_examin/lib/python3.9/site-packages/django/core/handlers/exception.py", line 55, in inner
    response = get_response(request)
  File "/home/an/python_examin/lib/python3.9/site-packages/django/core/handlers/base.py", line 197, in _get_response
    response = wrapped_callback(request, *callback_args, **callback_kwargs)
  File "/usr/local/lib/python3.9/contextlib.py", line 79, in inner
    return func(*args, **kwds)
  File "./StudentExamination/views.py", line 223, in add_index
    plat = json.loads(by)
  File "/usr/local/lib/python3.9/json/__init__.py", line 346, in loads
    return _default_decoder.decode(s)
  File "/usr/local/lib/python3.9/json/decoder.py", line 337, in decode
    obj, end = self.raw_decode(s, idx=_w(s, 0).end())
  File "/usr/local/lib/python3.9/json/decoder.py", line 353, in raw_decode
    obj, end = self.scan_once(s, idx)
json.decoder.JSONDecodeError: Expecting property name enclosed in double quotes: line 3 column 1 (char 17)
[2023-12-14 13:31:29,231] [log.py:241] [log:log_response] [ERROR]- Internal Server Error: /api/addmain/
Traceback (most recent call last):
  File "/home/an/python_examin/lib/python3.9/site-packages/django/core/handlers/exception.py", line 55, in inner
    response = get_response(request)
  File "/home/an/python_examin/lib/python3.9/site-packages/django/core/handlers/base.py", line 197, in _get_response
    response = wrapped_callback(request, *callback_args, **callback_kwargs)
  File "/usr/local/lib/python3.9/contextlib.py", line 79, in inner
    return func(*args, **kwds)
  File "./StudentExamination/views.py", line 223, in add_index
    plat = json.loads(by)
  File "/usr/local/lib/python3.9/json/__init__.py", line 346, in loads
    return _default_decoder.decode(s)
  File "/usr/local/lib/python3.9/json/decoder.py", line 340, in decode
    raise JSONDecodeError("Extra data", s, end)
json.decoder.JSONDecodeError: Extra data: line 14 column 1 (char 286)
[2023-12-14 13:31:45,459] [log.py:241] [log:log_response] [ERROR]- Internal Server Error: /api/addmain/
Traceback (most recent call last):
  File "/home/an/python_examin/lib/python3.9/site-packages/django/core/handlers/exception.py", line 55, in inner
    response = get_response(request)
  File "/home/an/python_examin/lib/python3.9/site-packages/django/core/handlers/base.py", line 197, in _get_response
    response = wrapped_callback(request, *callback_args, **callback_kwargs)
  File "/usr/local/lib/python3.9/contextlib.py", line 79, in inner
    return func(*args, **kwds)
  File "./StudentExamination/views.py", line 223, in add_index
    plat = json.loads(by)
  File "/usr/local/lib/python3.9/json/__init__.py", line 346, in loads
    return _default_decoder.decode(s)
  File "/usr/local/lib/python3.9/json/decoder.py", line 340, in decode
    raise JSONDecodeError("Extra data", s, end)
json.decoder.JSONDecodeError: Extra data: line 14 column 1 (char 350)
[2023-12-14 13:31:50,333] [log.py:241] [log:log_response] [ERROR]- Internal Server Error: /api/addmain/
Traceback (most recent call last):
  File "/home/an/python_examin/lib/python3.9/site-packages/django/core/handlers/exception.py", line 55, in inner
    response = get_response(request)
  File "/home/an/python_examin/lib/python3.9/site-packages/django/core/handlers/base.py", line 197, in _get_response
    response = wrapped_callback(request, *callback_args, **callback_kwargs)
  File "/usr/local/lib/python3.9/contextlib.py", line 79, in inner
    return func(*args, **kwds)
  File "./StudentExamination/views.py", line 223, in add_index
    plat = json.loads(by)
  File "/usr/local/lib/python3.9/json/__init__.py", line 346, in loads
    return _default_decoder.decode(s)
  File "/usr/local/lib/python3.9/json/decoder.py", line 340, in decode
    raise JSONDecodeError("Extra data", s, end)
json.decoder.JSONDecodeError: Extra data: line 14 column 1 (char 350)
[2023-12-14 13:31:54,939] [log.py:241] [log:log_response] [ERROR]- Internal Server Error: /api/addmain/
Traceback (most recent call last):
  File "/home/an/python_examin/lib/python3.9/site-packages/django/core/handlers/exception.py", line 55, in inner
    response = get_response(request)
  File "/home/an/python_examin/lib/python3.9/site-packages/django/core/handlers/base.py", line 197, in _get_response
    response = wrapped_callback(request, *callback_args, **callback_kwargs)
  File "/usr/local/lib/python3.9/contextlib.py", line 79, in inner
    return func(*args, **kwds)
  File "./StudentExamination/views.py", line 223, in add_index
    plat = json.loads(by)
  File "/usr/local/lib/python3.9/json/__init__.py", line 346, in loads
    return _default_decoder.decode(s)
  File "/usr/local/lib/python3.9/json/decoder.py", line 340, in decode
    raise JSONDecodeError("Extra data", s, end)
json.decoder.JSONDecodeError: Extra data: line 14 column 1 (char 350)
[2023-12-14 13:31:59,261] [log.py:241] [log:log_response] [ERROR]- Internal Server Error: /api/addmain/
Traceback (most recent call last):
  File "/home/an/python_examin/lib/python3.9/site-packages/django/core/handlers/exception.py", line 55, in inner
    response = get_response(request)
  File "/home/an/python_examin/lib/python3.9/site-packages/django/core/handlers/base.py", line 197, in _get_response
    response = wrapped_callback(request, *callback_args, **callback_kwargs)
  File "/usr/local/lib/python3.9/contextlib.py", line 79, in inner
    return func(*args, **kwds)
  File "./StudentExamination/views.py", line 223, in add_index
    plat = json.loads(by)
  File "/usr/local/lib/python3.9/json/__init__.py", line 346, in loads
    return _default_decoder.decode(s)
  File "/usr/local/lib/python3.9/json/decoder.py", line 340, in decode
    raise JSONDecodeError("Extra data", s, end)
json.decoder.JSONDecodeError: Extra data: line 14 column 1 (char 350)
[2023-12-14 13:32:14,029] [log.py:241] [log:log_response] [ERROR]- Internal Server Error: /api/addmain/
Traceback (most recent call last):
  File "/home/an/python_examin/lib/python3.9/site-packages/django/core/handlers/exception.py", line 55, in inner
    response = get_response(request)
  File "/home/an/python_examin/lib/python3.9/site-packages/django/core/handlers/base.py", line 197, in _get_response
    response = wrapped_callback(request, *callback_args, **callback_kwargs)
  File "/usr/local/lib/python3.9/contextlib.py", line 79, in inner
    return func(*args, **kwds)
  File "./StudentExamination/views.py", line 223, in add_index
    plat = json.loads(by)
  File "/usr/local/lib/python3.9/json/__init__.py", line 346, in loads
    return _default_decoder.decode(s)
  File "/usr/local/lib/python3.9/json/decoder.py", line 340, in decode
    raise JSONDecodeError("Extra data", s, end)
json.decoder.JSONDecodeError: Extra data: line 14 column 1 (char 354)
[2023-12-14 13:33:13,681] [log.py:241] [log:log_response] [ERROR]- Internal Server Error: /api/addmain/
Traceback (most recent call last):
  File "/home/an/python_examin/lib/python3.9/site-packages/django/core/handlers/exception.py", line 55, in inner
    response = get_response(request)
  File "/home/an/python_examin/lib/python3.9/site-packages/django/core/handlers/base.py", line 197, in _get_response
    response = wrapped_callback(request, *callback_args, **callback_kwargs)
  File "/usr/local/lib/python3.9/contextlib.py", line 79, in inner
    return func(*args, **kwds)
  File "./StudentExamination/views.py", line 223, in add_index
    plat = json.loads(by)
  File "/usr/local/lib/python3.9/json/__init__.py", line 346, in loads
    return _default_decoder.decode(s)
  File "/usr/local/lib/python3.9/json/decoder.py", line 340, in decode
    raise JSONDecodeError("Extra data", s, end)
json.decoder.JSONDecodeError: Extra data: line 14 column 1 (char 354)
[2023-12-14 13:43:23,675] [log.py:241] [log:log_response] [ERROR]- Internal Server Error: /api/addmain/
Traceback (most recent call last):
  File "/home/an/python_examin/lib/python3.9/site-packages/django/core/handlers/exception.py", line 55, in inner
    response = get_response(request)
  File "/home/an/python_examin/lib/python3.9/site-packages/django/core/handlers/base.py", line 197, in _get_response
    response = wrapped_callback(request, *callback_args, **callback_kwargs)
  File "/usr/local/lib/python3.9/contextlib.py", line 79, in inner
    return func(*args, **kwds)
  File "./StudentExamination/views.py", line 223, in add_index
    plat = json.loads(by)
  File "/usr/local/lib/python3.9/json/__init__.py", line 346, in loads
    return _default_decoder.decode(s)
  File "/usr/local/lib/python3.9/json/decoder.py", line 340, in decode
    raise JSONDecodeError("Extra data", s, end)
json.decoder.JSONDecodeError: Extra data: line 14 column 1 (char 354)
[2023-12-14 13:50:35,624] [log.py:241] [log:log_response] [ERROR]- Internal Server Error: /api/addmain/
Traceback (most recent call last):
  File "/home/an/python_examin/lib/python3.9/site-packages/django/core/handlers/exception.py", line 55, in inner
    response = get_response(request)
  File "/home/an/python_examin/lib/python3.9/site-packages/django/core/handlers/base.py", line 197, in _get_response
    response = wrapped_callback(request, *callback_args, **callback_kwargs)
  File "/usr/local/lib/python3.9/contextlib.py", line 79, in inner
    return func(*args, **kwds)
  File "./StudentExamination/views.py", line 223, in add_index
    plat = json.loads(by)
  File "/usr/local/lib/python3.9/json/__init__.py", line 346, in loads
    return _default_decoder.decode(s)
  File "/usr/local/lib/python3.9/json/decoder.py", line 340, in decode
    raise JSONDecodeError("Extra data", s, end)
json.decoder.JSONDecodeError: Extra data: line 14 column 1 (char 354)
[2023-12-14 13:59:41,904] [log.py:241] [log:log_response] [ERROR]- Internal Server Error: /api/addmain/
Traceback (most recent call last):
  File "/home/an/python_examin/lib/python3.9/site-packages/django/core/handlers/exception.py", line 55, in inner
    response = get_response(request)
  File "/home/an/python_examin/lib/python3.9/site-packages/django/core/handlers/base.py", line 197, in _get_response
    response = wrapped_callback(request, *callback_args, **callback_kwargs)
  File "/usr/local/lib/python3.9/contextlib.py", line 79, in inner
    return func(*args, **kwds)
  File "./StudentExamination/views.py", line 223, in add_index
    plat = json.loads(by)
  File "/usr/local/lib/python3.9/json/__init__.py", line 346, in loads
    return _default_decoder.decode(s)
  File "/usr/local/lib/python3.9/json/decoder.py", line 340, in decode
    raise JSONDecodeError("Extra data", s, end)
json.decoder.JSONDecodeError: Extra data: line 13 column 1 (char 343)
[2023-12-14 14:01:21,488] [log.py:241] [log:log_response] [ERROR]- Internal Server Error: /api/addmain/
Traceback (most recent call last):
  File "/home/an/python_examin/lib/python3.9/site-packages/django/core/handlers/exception.py", line 55, in inner
    response = get_response(request)
  File "/home/an/python_examin/lib/python3.9/site-packages/django/core/handlers/base.py", line 197, in _get_response
    response = wrapped_callback(request, *callback_args, **callback_kwargs)
  File "/usr/local/lib/python3.9/contextlib.py", line 79, in inner
    return func(*args, **kwds)
  File "./StudentExamination/views.py", line 223, in add_index
    plat = json.loads(by)
  File "/usr/local/lib/python3.9/json/__init__.py", line 346, in loads
    return _default_decoder.decode(s)
  File "/usr/local/lib/python3.9/json/decoder.py", line 340, in decode
    raise JSONDecodeError("Extra data", s, end)
json.decoder.JSONDecodeError: Extra data: line 14 column 1 (char 349)
[2023-12-15 07:02:26,372] [log.py:241] [log:log_response] [ERROR]- Internal Server Error: /api/addmain/
Traceback (most recent call last):
  File "/home/an/python_examin/lib/python3.9/site-packages/django/core/handlers/exception.py", line 55, in inner
    response = get_response(request)
  File "/home/an/python_examin/lib/python3.9/site-packages/django/core/handlers/base.py", line 197, in _get_response
    response = wrapped_callback(request, *callback_args, **callback_kwargs)
  File "/usr/local/lib/python3.9/contextlib.py", line 79, in inner
    return func(*args, **kwds)
  File "./StudentExamination/views.py", line 223, in add_index
    plat = json.loads(by)
  File "/usr/local/lib/python3.9/json/__init__.py", line 346, in loads
    return _default_decoder.decode(s)
  File "/usr/local/lib/python3.9/json/decoder.py", line 340, in decode
    raise JSONDecodeError("Extra data", s, end)
json.decoder.JSONDecodeError: Extra data: line 13 column 1 (char 343)
