[2023-12-15 16:03:52,744] [log.py:241] [log:log_response] [ERROR]- Internal Server Error: /api/addmain/
Traceback (most recent call last):
  File "D:\baiduwangpan\python_virtualenv\python_vx\lib\site-packages\django\core\handlers\exception.py", line 55, in inner
    response = get_response(request)
  File "D:\baiduwangpan\python_virtualenv\python_vx\lib\site-packages\django\core\handlers\base.py", line 197, in _get_response
    response = wrapped_callback(request, *callback_args, **callback_kwargs)
  File "D:\baiduwangpan\python\lib\contextlib.py", line 79, in inner
    return func(*args, **kwds)
  File "D:\02_Program\04_Examination\Examination\StudentExamination\views.py", line 222, in add_index
    by = dict(str(by))
ValueError: dictionary update sequence element #0 has length 1; 2 is required
[2023-12-15 16:03:52,776] [basehttp.py:187] [basehttp:log_message] [ERROR]- "POST /api/addmain/ HTTP/1.1" 500 145
[2023-12-15 08:47:45,119] [log.py:241] [log:log_response] [ERROR]- Internal Server Error: /api/addmain/
Traceback (most recent call last):
  File "/home/an/python_examin/lib/python3.9/site-packages/django/core/handlers/exception.py", line 55, in inner
    response = get_response(request)
  File "/home/an/python_examin/lib/python3.9/site-packages/django/core/handlers/base.py", line 197, in _get_response
    response = wrapped_callback(request, *callback_args, **callback_kwargs)
  File "/usr/local/lib/python3.9/contextlib.py", line 79, in inner
    return func(*args, **kwds)
  File "./StudentExamination/views.py", line 225, in add_index
    cf = check_field(plat)
  File "./StudentExamination/forms/ThirdParty.py", line 76, in check_field
    if int(field["purchaseState"]) not in [0, 1]:
ValueError: invalid literal for int() with base 10: 'a'
[2023-12-16 07:14:00,360] [log.py:241] [log:log_response] [ERROR]- Internal Server Error: /api/updata/
Traceback (most recent call last):
  File "/home/an/python_examin/lib/python3.9/site-packages/django/core/handlers/exception.py", line 55, in inner
    response = get_response(request)
  File "/home/an/python_examin/lib/python3.9/site-packages/django/core/handlers/base.py", line 197, in _get_response
    response = wrapped_callback(request, *callback_args, **callback_kwargs)
  File "/usr/local/lib/python3.9/contextlib.py", line 79, in inner
    return func(*args, **kwds)
  File "./StudentExamination/views.py", line 339, in updata_information
    cf = check_field(plat)
  File "./StudentExamination/forms/ThirdParty.py", line 58, in check_field
    if int(field["purchasePlatform"]) not in [0, 1, 2, 3]:
ValueError: invalid literal for int() with base 10: '京东'
[2023-12-16 07:15:56,272] [log.py:241] [log:log_response] [ERROR]- Internal Server Error: /api/updata/
Traceback (most recent call last):
  File "/home/an/python_examin/lib/python3.9/site-packages/django/core/handlers/exception.py", line 55, in inner
    response = get_response(request)
  File "/home/an/python_examin/lib/python3.9/site-packages/django/core/handlers/base.py", line 197, in _get_response
    response = wrapped_callback(request, *callback_args, **callback_kwargs)
  File "/usr/local/lib/python3.9/contextlib.py", line 79, in inner
    return func(*args, **kwds)
  File "./StudentExamination/views.py", line 339, in updata_information
    cf = check_field(plat)
  File "./StudentExamination/forms/ThirdParty.py", line 76, in check_field
    if int(field["purchaseState"]) not in [0, 1]:
ValueError: invalid literal for int() with base 10: '已结算'
[2023-12-16 07:16:52,415] [log.py:241] [log:log_response] [ERROR]- Internal Server Error: /api/updata/
Traceback (most recent call last):
  File "/home/an/python_examin/lib/python3.9/site-packages/django/core/handlers/exception.py", line 55, in inner
    response = get_response(request)
  File "/home/an/python_examin/lib/python3.9/site-packages/django/core/handlers/base.py", line 197, in _get_response
    response = wrapped_callback(request, *callback_args, **callback_kwargs)
  File "/usr/local/lib/python3.9/contextlib.py", line 79, in inner
    return func(*args, **kwds)
  File "./StudentExamination/views.py", line 339, in updata_information
    cf = check_field(plat)
  File "./StudentExamination/forms/ThirdParty.py", line 76, in check_field
    if int(field["purchaseState"]) not in [0, 1]:
ValueError: invalid literal for int() with base 10: '已结算'
